[2025-04-04T16:01:20.674+0000] {taskinstance.py:1083} INFO - Dependencies all met for <TaskInstance: download_and_store_images.download_and_upload_images scheduled__2024-02-13T00:00:00+00:00 [queued]>
[2025-04-04T16:01:21.015+0000] {taskinstance.py:1083} INFO - Dependencies all met for <TaskInstance: download_and_store_images.download_and_upload_images scheduled__2024-02-13T00:00:00+00:00 [queued]>
[2025-04-04T16:01:21.035+0000] {taskinstance.py:1279} INFO - 
--------------------------------------------------------------------------------
[2025-04-04T16:01:21.056+0000] {taskinstance.py:1280} INFO - Starting attempt 2 of 2
[2025-04-04T16:01:21.170+0000] {taskinstance.py:1281} INFO - 
--------------------------------------------------------------------------------
[2025-04-04T16:01:23.927+0000] {taskinstance.py:1300} INFO - Executing <Task(PythonOperator): download_and_upload_images> on 2024-02-13 00:00:00+00:00
[2025-04-04T16:01:24.082+0000] {standard_task_runner.py:55} INFO - Started process 1216 to run task
[2025-04-04T16:01:24.160+0000] {standard_task_runner.py:82} INFO - Running: ['***', 'tasks', 'run', 'download_and_store_images', 'download_and_upload_images', 'scheduled__2024-02-13T00:00:00+00:00', '--job-id', '827', '--raw', '--subdir', 'DAGS_FOLDER/dag_data_collect.py', '--cfg-path', '/tmp/tmpx3w1qbgb']
[2025-04-04T16:01:24.175+0000] {standard_task_runner.py:83} INFO - Job 827: Subtask download_and_upload_images
[2025-04-04T16:01:29.905+0000] {warnings.py:110} WARNING - /home/***/.local/lib/python3.7/site-packages/***/settings.py:249: DeprecationWarning: The sql_alchemy_conn option in [core] has been moved to the sql_alchemy_conn option in [database] - the old setting has been used, but please update your config.
  SQL_ALCHEMY_CONN = conf.get("database", "SQL_ALCHEMY_CONN")

[2025-04-04T16:01:33.076+0000] {warnings.py:110} WARNING - /home/***/.local/lib/python3.7/site-packages/***/utils/sqlalchemy.py:124: DeprecationWarning: The sql_alchemy_conn option in [core] has been moved to the sql_alchemy_conn option in [database] - the old setting has been used, but please update your config.
  return not conf.get("database", "sql_alchemy_conn").startswith("mssql")

[2025-04-04T16:01:53.457+0000] {task_command.py:388} INFO - Running <TaskInstance: download_and_store_images.download_and_upload_images scheduled__2024-02-13T00:00:00+00:00 [running]> on host fd5deae9c635
[2025-04-04T16:02:13.303+0000] {taskinstance.py:1509} INFO - Exporting the following env vars:
AIRFLOW_CTX_DAG_OWNER=***
AIRFLOW_CTX_DAG_ID=download_and_store_images
AIRFLOW_CTX_TASK_ID=download_and_upload_images
AIRFLOW_CTX_EXECUTION_DATE=2024-02-13T00:00:00+00:00
AIRFLOW_CTX_TRY_NUMBER=2
AIRFLOW_CTX_DAG_RUN_ID=scheduled__2024-02-13T00:00:00+00:00
[2025-04-04T16:02:17.342+0000] {base.py:73} INFO - Using connection ID 'minio_s3' for task execution.
[2025-04-04T16:02:17.384+0000] {connection_wrapper.py:334} INFO - AWS Connection (conn_id='minio_s3', conn_type='aws') credentials retrieved from login and password.
[2025-04-04T16:02:17.892+0000] {warnings.py:110} WARNING - /home/***/.local/lib/python3.7/site-packages/***/providers/amazon/aws/utils/connection_wrapper.py:8: DeprecationWarning: extra['host'] is deprecated and will be removed in a future release. Please set extra['endpoint_url'] instead
  #

[2025-04-04T16:06:01.350+0000] {base.py:73} INFO - Using connection ID 'minio_s3' for task execution.
[2025-04-04T16:06:01.458+0000] {connection_wrapper.py:334} INFO - AWS Connection (conn_id='minio_s3', conn_type='aws') credentials retrieved from login and password.
[2025-04-04T16:06:40.639+0000] {base_job.py:243} ERROR - LocalTaskJob heartbeat got an exception
Traceback (most recent call last):
  File "/home/airflow/.local/lib/python3.7/site-packages/sqlalchemy/engine/base.py", line 3361, in _wrap_pool_connect
    return fn()
  File "/home/airflow/.local/lib/python3.7/site-packages/sqlalchemy/pool/base.py", line 327, in connect
    return _ConnectionFairy._checkout(self)
  File "/home/airflow/.local/lib/python3.7/site-packages/sqlalchemy/pool/base.py", line 894, in _checkout
    fairy = _ConnectionRecord.checkout(pool)
  File "/home/airflow/.local/lib/python3.7/site-packages/sqlalchemy/pool/base.py", line 493, in checkout
    rec = pool._do_get()
  File "/home/airflow/.local/lib/python3.7/site-packages/sqlalchemy/pool/impl.py", line 256, in _do_get
    return self._create_connection()
  File "/home/airflow/.local/lib/python3.7/site-packages/sqlalchemy/pool/base.py", line 273, in _create_connection
    return _ConnectionRecord(self)
  File "/home/airflow/.local/lib/python3.7/site-packages/sqlalchemy/pool/base.py", line 388, in __init__
    self.__connect()
  File "/home/airflow/.local/lib/python3.7/site-packages/sqlalchemy/pool/base.py", line 691, in __connect
    pool.logger.debug("Error on connect(): %s", e)
  File "/home/airflow/.local/lib/python3.7/site-packages/sqlalchemy/util/langhelpers.py", line 72, in __exit__
    with_traceback=exc_tb,
  File "/home/airflow/.local/lib/python3.7/site-packages/sqlalchemy/util/compat.py", line 211, in raise_
    raise exception
  File "/home/airflow/.local/lib/python3.7/site-packages/sqlalchemy/pool/base.py", line 686, in __connect
    self.dbapi_connection = connection = pool._invoke_creator(self)
  File "/home/airflow/.local/lib/python3.7/site-packages/sqlalchemy/engine/create.py", line 578, in connect
    return dialect.connect(*cargs, **cparams)
  File "/home/airflow/.local/lib/python3.7/site-packages/sqlalchemy/engine/default.py", line 598, in connect
    return self.dbapi.connect(*cargs, **cparams)
  File "/home/airflow/.local/lib/python3.7/site-packages/psycopg2/__init__.py", line 122, in connect
    conn = _connect(dsn, connection_factory=connection_factory, **kwasync)
psycopg2.OperationalError: could not translate host name "postgres" to address: Temporary failure in name resolution


The above exception was the direct cause of the following exception:

Traceback (most recent call last):
  File "/home/airflow/.local/lib/python3.7/site-packages/airflow/jobs/base_job.py", line 233, in heartbeat
    session.merge(self)
  File "/home/airflow/.local/lib/python3.7/site-packages/sqlalchemy/orm/session.py", line 3057, in merge
    _resolve_conflict_map=_resolve_conflict_map,
  File "/home/airflow/.local/lib/python3.7/site-packages/sqlalchemy/orm/session.py", line 3135, in _merge
    options=options,
  File "/home/airflow/.local/lib/python3.7/site-packages/sqlalchemy/orm/session.py", line 2856, in get
    execution_options=execution_options,
  File "/home/airflow/.local/lib/python3.7/site-packages/sqlalchemy/orm/session.py", line 2974, in _get_impl
    load_options=load_options,
  File "/home/airflow/.local/lib/python3.7/site-packages/sqlalchemy/orm/loading.py", line 534, in load_on_pk_identity
    bind_arguments=bind_arguments,
  File "/home/airflow/.local/lib/python3.7/site-packages/sqlalchemy/orm/session.py", line 1713, in execute
    conn = self._connection_for_bind(bind)
  File "/home/airflow/.local/lib/python3.7/site-packages/sqlalchemy/orm/session.py", line 1553, in _connection_for_bind
    engine, execution_options
  File "/home/airflow/.local/lib/python3.7/site-packages/sqlalchemy/orm/session.py", line 747, in _connection_for_bind
    conn = bind.connect()
  File "/home/airflow/.local/lib/python3.7/site-packages/sqlalchemy/engine/base.py", line 3315, in connect
    return self._connection_cls(self, close_with_result=close_with_result)
  File "/home/airflow/.local/lib/python3.7/site-packages/sqlalchemy/engine/base.py", line 96, in __init__
    else engine.raw_connection()
  File "/home/airflow/.local/lib/python3.7/site-packages/sqlalchemy/engine/base.py", line 3394, in raw_connection
    return self._wrap_pool_connect(self.pool.connect, _connection)
  File "/home/airflow/.local/lib/python3.7/site-packages/sqlalchemy/engine/base.py", line 3365, in _wrap_pool_connect
    e, dialect, self
  File "/home/airflow/.local/lib/python3.7/site-packages/sqlalchemy/engine/base.py", line 2199, in _handle_dbapi_exception_noconnection
    sqlalchemy_exception, with_traceback=exc_info[2], from_=e
  File "/home/airflow/.local/lib/python3.7/site-packages/sqlalchemy/util/compat.py", line 211, in raise_
    raise exception
  File "/home/airflow/.local/lib/python3.7/site-packages/sqlalchemy/engine/base.py", line 3361, in _wrap_pool_connect
    return fn()
  File "/home/airflow/.local/lib/python3.7/site-packages/sqlalchemy/pool/base.py", line 327, in connect
    return _ConnectionFairy._checkout(self)
  File "/home/airflow/.local/lib/python3.7/site-packages/sqlalchemy/pool/base.py", line 894, in _checkout
    fairy = _ConnectionRecord.checkout(pool)
  File "/home/airflow/.local/lib/python3.7/site-packages/sqlalchemy/pool/base.py", line 493, in checkout
    rec = pool._do_get()
  File "/home/airflow/.local/lib/python3.7/site-packages/sqlalchemy/pool/impl.py", line 256, in _do_get
    return self._create_connection()
  File "/home/airflow/.local/lib/python3.7/site-packages/sqlalchemy/pool/base.py", line 273, in _create_connection
    return _ConnectionRecord(self)
  File "/home/airflow/.local/lib/python3.7/site-packages/sqlalchemy/pool/base.py", line 388, in __init__
    self.__connect()
  File "/home/airflow/.local/lib/python3.7/site-packages/sqlalchemy/pool/base.py", line 691, in __connect
    pool.logger.debug("Error on connect(): %s", e)
  File "/home/airflow/.local/lib/python3.7/site-packages/sqlalchemy/util/langhelpers.py", line 72, in __exit__
    with_traceback=exc_tb,
  File "/home/airflow/.local/lib/python3.7/site-packages/sqlalchemy/util/compat.py", line 211, in raise_
    raise exception
  File "/home/airflow/.local/lib/python3.7/site-packages/sqlalchemy/pool/base.py", line 686, in __connect
    self.dbapi_connection = connection = pool._invoke_creator(self)
  File "/home/airflow/.local/lib/python3.7/site-packages/sqlalchemy/engine/create.py", line 578, in connect
    return dialect.connect(*cargs, **cparams)
  File "/home/airflow/.local/lib/python3.7/site-packages/sqlalchemy/engine/default.py", line 598, in connect
    return self.dbapi.connect(*cargs, **cparams)
  File "/home/airflow/.local/lib/python3.7/site-packages/psycopg2/__init__.py", line 122, in connect
    conn = _connect(dsn, connection_factory=connection_factory, **kwasync)
sqlalchemy.exc.OperationalError: (psycopg2.OperationalError) could not translate host name "postgres" to address: Temporary failure in name resolution

(Background on this error at: https://sqlalche.me/e/14/e3q8)
[2025-04-04T16:06:52.226+0000] {base.py:73} INFO - Using connection ID 'minio_s3' for task execution.
[2025-04-04T16:06:52.284+0000] {connection_wrapper.py:334} INFO - AWS Connection (conn_id='minio_s3', conn_type='aws') credentials retrieved from login and password.
[2025-04-04T16:06:58.258+0000] {base.py:73} INFO - Using connection ID 'minio_s3' for task execution.
[2025-04-04T16:06:58.267+0000] {connection_wrapper.py:334} INFO - AWS Connection (conn_id='minio_s3', conn_type='aws') credentials retrieved from login and password.
[2025-04-04T16:07:07.635+0000] {base.py:73} INFO - Using connection ID 'minio_s3' for task execution.
[2025-04-04T16:07:07.640+0000] {connection_wrapper.py:334} INFO - AWS Connection (conn_id='minio_s3', conn_type='aws') credentials retrieved from login and password.
[2025-04-04T16:07:15.444+0000] {base.py:73} INFO - Using connection ID 'minio_s3' for task execution.
[2025-04-04T16:07:15.458+0000] {connection_wrapper.py:334} INFO - AWS Connection (conn_id='minio_s3', conn_type='aws') credentials retrieved from login and password.
[2025-04-04T16:07:26.840+0000] {base.py:73} INFO - Using connection ID 'minio_s3' for task execution.
[2025-04-04T16:07:26.886+0000] {connection_wrapper.py:334} INFO - AWS Connection (conn_id='minio_s3', conn_type='aws') credentials retrieved from login and password.
[2025-04-04T16:07:31.791+0000] {base.py:73} INFO - Using connection ID 'minio_s3' for task execution.
[2025-04-04T16:07:31.820+0000] {connection_wrapper.py:334} INFO - AWS Connection (conn_id='minio_s3', conn_type='aws') credentials retrieved from login and password.
[2025-04-04T16:07:42.033+0000] {base.py:73} INFO - Using connection ID 'minio_s3' for task execution.
[2025-04-04T16:07:42.041+0000] {connection_wrapper.py:334} INFO - AWS Connection (conn_id='minio_s3', conn_type='aws') credentials retrieved from login and password.
[2025-04-04T16:07:51.956+0000] {base.py:73} INFO - Using connection ID 'minio_s3' for task execution.
[2025-04-04T16:07:51.974+0000] {connection_wrapper.py:334} INFO - AWS Connection (conn_id='minio_s3', conn_type='aws') credentials retrieved from login and password.
[2025-04-04T16:08:10.034+0000] {base.py:73} INFO - Using connection ID 'minio_s3' for task execution.
[2025-04-04T16:08:10.102+0000] {connection_wrapper.py:334} INFO - AWS Connection (conn_id='minio_s3', conn_type='aws') credentials retrieved from login and password.
[2025-04-04T16:08:21.737+0000] {base.py:73} INFO - Using connection ID 'minio_s3' for task execution.
[2025-04-04T16:08:21.758+0000] {connection_wrapper.py:334} INFO - AWS Connection (conn_id='minio_s3', conn_type='aws') credentials retrieved from login and password.
[2025-04-04T16:08:32.215+0000] {base.py:73} INFO - Using connection ID 'minio_s3' for task execution.
[2025-04-04T16:08:32.220+0000] {connection_wrapper.py:334} INFO - AWS Connection (conn_id='minio_s3', conn_type='aws') credentials retrieved from login and password.
[2025-04-04T16:08:45.668+0000] {base.py:73} INFO - Using connection ID 'minio_s3' for task execution.
[2025-04-04T16:08:45.710+0000] {connection_wrapper.py:334} INFO - AWS Connection (conn_id='minio_s3', conn_type='aws') credentials retrieved from login and password.
[2025-04-04T16:08:58.419+0000] {base.py:73} INFO - Using connection ID 'minio_s3' for task execution.
[2025-04-04T16:08:58.430+0000] {connection_wrapper.py:334} INFO - AWS Connection (conn_id='minio_s3', conn_type='aws') credentials retrieved from login and password.
[2025-04-04T16:09:11.436+0000] {base.py:73} INFO - Using connection ID 'minio_s3' for task execution.
[2025-04-04T16:09:11.472+0000] {connection_wrapper.py:334} INFO - AWS Connection (conn_id='minio_s3', conn_type='aws') credentials retrieved from login and password.
[2025-04-04T16:09:26.707+0000] {base.py:73} INFO - Using connection ID 'minio_s3' for task execution.
[2025-04-04T16:09:26.731+0000] {connection_wrapper.py:334} INFO - AWS Connection (conn_id='minio_s3', conn_type='aws') credentials retrieved from login and password.
[2025-04-04T16:10:22.443+0000] {base.py:73} INFO - Using connection ID 'minio_s3' for task execution.
[2025-04-04T16:10:22.490+0000] {connection_wrapper.py:334} INFO - AWS Connection (conn_id='minio_s3', conn_type='aws') credentials retrieved from login and password.
[2025-04-04T16:10:55.878+0000] {base.py:73} INFO - Using connection ID 'minio_s3' for task execution.
[2025-04-04T16:10:55.966+0000] {connection_wrapper.py:334} INFO - AWS Connection (conn_id='minio_s3', conn_type='aws') credentials retrieved from login and password.
[2025-04-04T16:11:26.758+0000] {base.py:73} INFO - Using connection ID 'minio_s3' for task execution.
[2025-04-04T16:11:26.807+0000] {connection_wrapper.py:334} INFO - AWS Connection (conn_id='minio_s3', conn_type='aws') credentials retrieved from login and password.
[2025-04-04T16:11:51.135+0000] {base.py:73} INFO - Using connection ID 'minio_s3' for task execution.
[2025-04-04T16:11:51.145+0000] {connection_wrapper.py:334} INFO - AWS Connection (conn_id='minio_s3', conn_type='aws') credentials retrieved from login and password.
[2025-04-04T16:12:03.599+0000] {base.py:73} INFO - Using connection ID 'minio_s3' for task execution.
[2025-04-04T16:12:03.757+0000] {connection_wrapper.py:334} INFO - AWS Connection (conn_id='minio_s3', conn_type='aws') credentials retrieved from login and password.
[2025-04-04T16:12:37.394+0000] {base.py:73} INFO - Using connection ID 'minio_s3' for task execution.
[2025-04-04T16:12:37.459+0000] {connection_wrapper.py:334} INFO - AWS Connection (conn_id='minio_s3', conn_type='aws') credentials retrieved from login and password.
[2025-04-04T16:15:39.860+0000] {base.py:73} INFO - Using connection ID 'minio_s3' for task execution.
[2025-04-04T16:15:39.868+0000] {connection_wrapper.py:334} INFO - AWS Connection (conn_id='minio_s3', conn_type='aws') credentials retrieved from login and password.
[2025-04-04T16:18:15.252+0000] {base.py:73} INFO - Using connection ID 'minio_s3' for task execution.
[2025-04-04T16:18:15.326+0000] {connection_wrapper.py:334} INFO - AWS Connection (conn_id='minio_s3', conn_type='aws') credentials retrieved from login and password.
[2025-04-04T16:19:10.054+0000] {base.py:73} INFO - Using connection ID 'minio_s3' for task execution.
[2025-04-04T16:19:10.076+0000] {connection_wrapper.py:334} INFO - AWS Connection (conn_id='minio_s3', conn_type='aws') credentials retrieved from login and password.
[2025-04-04T16:19:17.816+0000] {base.py:73} INFO - Using connection ID 'minio_s3' for task execution.
[2025-04-04T16:19:17.830+0000] {connection_wrapper.py:334} INFO - AWS Connection (conn_id='minio_s3', conn_type='aws') credentials retrieved from login and password.
[2025-04-04T16:19:24.110+0000] {base.py:73} INFO - Using connection ID 'minio_s3' for task execution.
[2025-04-04T16:19:24.114+0000] {connection_wrapper.py:334} INFO - AWS Connection (conn_id='minio_s3', conn_type='aws') credentials retrieved from login and password.
[2025-04-04T16:19:27.265+0000] {base.py:73} INFO - Using connection ID 'minio_s3' for task execution.
[2025-04-04T16:19:27.272+0000] {connection_wrapper.py:334} INFO - AWS Connection (conn_id='minio_s3', conn_type='aws') credentials retrieved from login and password.
[2025-04-04T16:19:34.368+0000] {base.py:73} INFO - Using connection ID 'minio_s3' for task execution.
[2025-04-04T16:19:34.370+0000] {connection_wrapper.py:334} INFO - AWS Connection (conn_id='minio_s3', conn_type='aws') credentials retrieved from login and password.
[2025-04-04T16:19:39.765+0000] {base.py:73} INFO - Using connection ID 'minio_s3' for task execution.
[2025-04-04T16:19:39.770+0000] {connection_wrapper.py:334} INFO - AWS Connection (conn_id='minio_s3', conn_type='aws') credentials retrieved from login and password.
[2025-04-04T16:19:43.069+0000] {base.py:73} INFO - Using connection ID 'minio_s3' for task execution.
[2025-04-04T16:19:43.102+0000] {connection_wrapper.py:334} INFO - AWS Connection (conn_id='minio_s3', conn_type='aws') credentials retrieved from login and password.
[2025-04-04T16:19:49.172+0000] {base.py:73} INFO - Using connection ID 'minio_s3' for task execution.
[2025-04-04T16:19:49.192+0000] {connection_wrapper.py:334} INFO - AWS Connection (conn_id='minio_s3', conn_type='aws') credentials retrieved from login and password.
[2025-04-04T16:19:55.563+0000] {base.py:73} INFO - Using connection ID 'minio_s3' for task execution.
[2025-04-04T16:19:55.576+0000] {connection_wrapper.py:334} INFO - AWS Connection (conn_id='minio_s3', conn_type='aws') credentials retrieved from login and password.
[2025-04-04T16:20:05.516+0000] {base.py:73} INFO - Using connection ID 'minio_s3' for task execution.
[2025-04-04T16:20:05.536+0000] {connection_wrapper.py:334} INFO - AWS Connection (conn_id='minio_s3', conn_type='aws') credentials retrieved from login and password.
[2025-04-04T16:20:15.158+0000] {base.py:73} INFO - Using connection ID 'minio_s3' for task execution.
[2025-04-04T16:20:15.288+0000] {connection_wrapper.py:334} INFO - AWS Connection (conn_id='minio_s3', conn_type='aws') credentials retrieved from login and password.
[2025-04-04T16:20:27.721+0000] {base.py:73} INFO - Using connection ID 'minio_s3' for task execution.
[2025-04-04T16:20:27.831+0000] {connection_wrapper.py:334} INFO - AWS Connection (conn_id='minio_s3', conn_type='aws') credentials retrieved from login and password.
[2025-04-04T16:20:41.331+0000] {base.py:73} INFO - Using connection ID 'minio_s3' for task execution.
[2025-04-04T16:20:41.335+0000] {connection_wrapper.py:334} INFO - AWS Connection (conn_id='minio_s3', conn_type='aws') credentials retrieved from login and password.
[2025-04-04T16:21:00.656+0000] {base.py:73} INFO - Using connection ID 'minio_s3' for task execution.
[2025-04-04T16:21:00.713+0000] {connection_wrapper.py:334} INFO - AWS Connection (conn_id='minio_s3', conn_type='aws') credentials retrieved from login and password.
[2025-04-04T16:21:28.266+0000] {base.py:73} INFO - Using connection ID 'minio_s3' for task execution.
[2025-04-04T16:21:28.301+0000] {connection_wrapper.py:334} INFO - AWS Connection (conn_id='minio_s3', conn_type='aws') credentials retrieved from login and password.
[2025-04-04T16:22:56.151+0000] {base.py:73} INFO - Using connection ID 'minio_s3' for task execution.
[2025-04-04T16:22:56.754+0000] {connection_wrapper.py:334} INFO - AWS Connection (conn_id='minio_s3', conn_type='aws') credentials retrieved from login and password.
[2025-04-04T16:24:02.571+0000] {local_task_job.py:273} WARNING - State of this instance has been externally set to failed. Terminating instance.
[2025-04-04T16:24:02.887+0000] {process_utils.py:133} INFO - Sending Signals.SIGTERM to group 1216. PIDs of all processes in the group: [1216]
[2025-04-04T16:24:02.890+0000] {process_utils.py:84} INFO - Sending the signal Signals.SIGTERM to group 1216
[2025-04-04T16:24:02.901+0000] {taskinstance.py:1479} ERROR - Received SIGTERM. Terminating subprocesses.
[2025-04-04T16:24:04.962+0000] {process_utils.py:79} INFO - Process psutil.Process(pid=1216, status='terminated', exitcode=0, started='16:01:23') (1216) terminated with exit code 0
