[2025-04-04T10:19:43.128+0000] {taskinstance.py:1083} INFO - Dependencies all met for <TaskInstance: download_and_store_images.download_and_upload_images scheduled__2024-02-01T00:00:00+00:00 [queued]>
[2025-04-04T10:19:43.302+0000] {taskinstance.py:1083} INFO - Dependencies all met for <TaskInstance: download_and_store_images.download_and_upload_images scheduled__2024-02-01T00:00:00+00:00 [queued]>
[2025-04-04T10:19:43.306+0000] {taskinstance.py:1279} INFO - 
--------------------------------------------------------------------------------
[2025-04-04T10:19:43.307+0000] {taskinstance.py:1280} INFO - Starting attempt 1 of 2
[2025-04-04T10:19:43.308+0000] {taskinstance.py:1281} INFO - 
--------------------------------------------------------------------------------
[2025-04-04T10:19:43.998+0000] {taskinstance.py:1300} INFO - Executing <Task(PythonOperator): download_and_upload_images> on 2024-02-01 00:00:00+00:00
[2025-04-04T10:19:44.309+0000] {standard_task_runner.py:55} INFO - Started process 96 to run task
[2025-04-04T10:19:47.023+0000] {standard_task_runner.py:82} INFO - Running: ['***', 'tasks', 'run', 'download_and_store_images', 'download_and_upload_images', 'scheduled__2024-02-01T00:00:00+00:00', '--job-id', '782', '--raw', '--subdir', 'DAGS_FOLDER/dag_data_collect.py', '--cfg-path', '/tmp/tmphsvkzxkc']
[2025-04-04T10:19:47.054+0000] {standard_task_runner.py:83} INFO - Job 782: Subtask download_and_upload_images
[2025-04-04T10:19:48.365+0000] {warnings.py:110} WARNING - /home/***/.local/lib/python3.7/site-packages/***/settings.py:249: DeprecationWarning: The sql_alchemy_conn option in [core] has been moved to the sql_alchemy_conn option in [database] - the old setting has been used, but please update your config.
  SQL_ALCHEMY_CONN = conf.get("database", "SQL_ALCHEMY_CONN")

[2025-04-04T10:19:49.169+0000] {warnings.py:110} WARNING - /home/***/.local/lib/python3.7/site-packages/***/utils/sqlalchemy.py:124: DeprecationWarning: The sql_alchemy_conn option in [core] has been moved to the sql_alchemy_conn option in [database] - the old setting has been used, but please update your config.
  return not conf.get("database", "sql_alchemy_conn").startswith("mssql")

[2025-04-04T10:19:49.634+0000] {task_command.py:388} INFO - Running <TaskInstance: download_and_store_images.download_and_upload_images scheduled__2024-02-01T00:00:00+00:00 [running]> on host 0df80d73d4ff
[2025-04-04T10:19:51.334+0000] {taskinstance.py:1509} INFO - Exporting the following env vars:
AIRFLOW_CTX_DAG_OWNER=***
AIRFLOW_CTX_DAG_ID=download_and_store_images
AIRFLOW_CTX_TASK_ID=download_and_upload_images
AIRFLOW_CTX_EXECUTION_DATE=2024-02-01T00:00:00+00:00
AIRFLOW_CTX_TRY_NUMBER=1
AIRFLOW_CTX_DAG_RUN_ID=scheduled__2024-02-01T00:00:00+00:00
[2025-04-04T10:19:53.655+0000] {base.py:73} INFO - Using connection ID 'minio_s3' for task execution.
[2025-04-04T10:19:53.664+0000] {connection_wrapper.py:334} INFO - AWS Connection (conn_id='minio_s3', conn_type='aws') credentials retrieved from login and password.
[2025-04-04T10:19:53.667+0000] {warnings.py:110} WARNING - /home/***/.local/lib/python3.7/site-packages/***/providers/amazon/aws/utils/connection_wrapper.py:8: DeprecationWarning: extra['host'] is deprecated and will be removed in a future release. Please set extra['endpoint_url'] instead
  #

[2025-04-04T10:20:16.623+0000] {base.py:73} INFO - Using connection ID 'minio_s3' for task execution.
[2025-04-04T10:20:16.666+0000] {connection_wrapper.py:334} INFO - AWS Connection (conn_id='minio_s3', conn_type='aws') credentials retrieved from login and password.
[2025-04-04T10:20:56.200+0000] {base.py:73} INFO - Using connection ID 'minio_s3' for task execution.
[2025-04-04T10:20:56.220+0000] {connection_wrapper.py:334} INFO - AWS Connection (conn_id='minio_s3', conn_type='aws') credentials retrieved from login and password.
[2025-04-04T10:21:08.741+0000] {base.py:73} INFO - Using connection ID 'minio_s3' for task execution.
[2025-04-04T10:21:08.801+0000] {connection_wrapper.py:334} INFO - AWS Connection (conn_id='minio_s3', conn_type='aws') credentials retrieved from login and password.
[2025-04-04T10:21:17.276+0000] {base.py:73} INFO - Using connection ID 'minio_s3' for task execution.
[2025-04-04T10:21:17.287+0000] {connection_wrapper.py:334} INFO - AWS Connection (conn_id='minio_s3', conn_type='aws') credentials retrieved from login and password.
[2025-04-04T10:21:23.441+0000] {base.py:73} INFO - Using connection ID 'minio_s3' for task execution.
[2025-04-04T10:21:23.447+0000] {connection_wrapper.py:334} INFO - AWS Connection (conn_id='minio_s3', conn_type='aws') credentials retrieved from login and password.
[2025-04-04T10:21:33.112+0000] {base.py:73} INFO - Using connection ID 'minio_s3' for task execution.
[2025-04-04T10:21:33.122+0000] {connection_wrapper.py:334} INFO - AWS Connection (conn_id='minio_s3', conn_type='aws') credentials retrieved from login and password.
[2025-04-04T10:21:39.785+0000] {base.py:73} INFO - Using connection ID 'minio_s3' for task execution.
[2025-04-04T10:21:39.794+0000] {connection_wrapper.py:334} INFO - AWS Connection (conn_id='minio_s3', conn_type='aws') credentials retrieved from login and password.
[2025-04-04T10:21:43.171+0000] {base.py:73} INFO - Using connection ID 'minio_s3' for task execution.
[2025-04-04T10:21:43.178+0000] {connection_wrapper.py:334} INFO - AWS Connection (conn_id='minio_s3', conn_type='aws') credentials retrieved from login and password.
[2025-04-04T10:21:50.887+0000] {base.py:73} INFO - Using connection ID 'minio_s3' for task execution.
[2025-04-04T10:21:50.908+0000] {connection_wrapper.py:334} INFO - AWS Connection (conn_id='minio_s3', conn_type='aws') credentials retrieved from login and password.
[2025-04-04T10:21:57.048+0000] {base.py:73} INFO - Using connection ID 'minio_s3' for task execution.
[2025-04-04T10:21:57.086+0000] {connection_wrapper.py:334} INFO - AWS Connection (conn_id='minio_s3', conn_type='aws') credentials retrieved from login and password.
[2025-04-04T10:22:00.160+0000] {base.py:73} INFO - Using connection ID 'minio_s3' for task execution.
[2025-04-04T10:22:00.166+0000] {connection_wrapper.py:334} INFO - AWS Connection (conn_id='minio_s3', conn_type='aws') credentials retrieved from login and password.
[2025-04-04T10:22:06.189+0000] {base.py:73} INFO - Using connection ID 'minio_s3' for task execution.
[2025-04-04T10:22:06.194+0000] {connection_wrapper.py:334} INFO - AWS Connection (conn_id='minio_s3', conn_type='aws') credentials retrieved from login and password.
[2025-04-04T10:22:15.939+0000] {base.py:73} INFO - Using connection ID 'minio_s3' for task execution.
[2025-04-04T10:22:15.942+0000] {connection_wrapper.py:334} INFO - AWS Connection (conn_id='minio_s3', conn_type='aws') credentials retrieved from login and password.
[2025-04-04T10:22:20.421+0000] {base.py:73} INFO - Using connection ID 'minio_s3' for task execution.
[2025-04-04T10:22:20.426+0000] {connection_wrapper.py:334} INFO - AWS Connection (conn_id='minio_s3', conn_type='aws') credentials retrieved from login and password.
[2025-04-04T10:22:25.209+0000] {base.py:73} INFO - Using connection ID 'minio_s3' for task execution.
[2025-04-04T10:22:25.213+0000] {connection_wrapper.py:334} INFO - AWS Connection (conn_id='minio_s3', conn_type='aws') credentials retrieved from login and password.
[2025-04-04T10:22:30.844+0000] {base.py:73} INFO - Using connection ID 'minio_s3' for task execution.
[2025-04-04T10:22:30.848+0000] {connection_wrapper.py:334} INFO - AWS Connection (conn_id='minio_s3', conn_type='aws') credentials retrieved from login and password.
[2025-04-04T10:22:34.763+0000] {base.py:73} INFO - Using connection ID 'minio_s3' for task execution.
[2025-04-04T10:22:34.768+0000] {connection_wrapper.py:334} INFO - AWS Connection (conn_id='minio_s3', conn_type='aws') credentials retrieved from login and password.
[2025-04-04T10:22:38.500+0000] {base.py:73} INFO - Using connection ID 'minio_s3' for task execution.
[2025-04-04T10:22:38.507+0000] {connection_wrapper.py:334} INFO - AWS Connection (conn_id='minio_s3', conn_type='aws') credentials retrieved from login and password.
[2025-04-04T10:22:42.220+0000] {base.py:73} INFO - Using connection ID 'minio_s3' for task execution.
[2025-04-04T10:22:42.228+0000] {connection_wrapper.py:334} INFO - AWS Connection (conn_id='minio_s3', conn_type='aws') credentials retrieved from login and password.
[2025-04-04T10:22:49.165+0000] {base.py:73} INFO - Using connection ID 'minio_s3' for task execution.
[2025-04-04T10:22:49.177+0000] {connection_wrapper.py:334} INFO - AWS Connection (conn_id='minio_s3', conn_type='aws') credentials retrieved from login and password.
[2025-04-04T10:22:52.608+0000] {base.py:73} INFO - Using connection ID 'minio_s3' for task execution.
[2025-04-04T10:22:52.611+0000] {connection_wrapper.py:334} INFO - AWS Connection (conn_id='minio_s3', conn_type='aws') credentials retrieved from login and password.
[2025-04-04T10:22:56.194+0000] {base.py:73} INFO - Using connection ID 'minio_s3' for task execution.
[2025-04-04T10:22:56.233+0000] {connection_wrapper.py:334} INFO - AWS Connection (conn_id='minio_s3', conn_type='aws') credentials retrieved from login and password.
[2025-04-04T10:23:02.519+0000] {base.py:73} INFO - Using connection ID 'minio_s3' for task execution.
[2025-04-04T10:23:02.521+0000] {connection_wrapper.py:334} INFO - AWS Connection (conn_id='minio_s3', conn_type='aws') credentials retrieved from login and password.
[2025-04-04T10:23:13.288+0000] {base.py:73} INFO - Using connection ID 'minio_s3' for task execution.
[2025-04-04T10:23:13.328+0000] {connection_wrapper.py:334} INFO - AWS Connection (conn_id='minio_s3', conn_type='aws') credentials retrieved from login and password.
[2025-04-04T10:23:17.144+0000] {base.py:73} INFO - Using connection ID 'minio_s3' for task execution.
[2025-04-04T10:23:17.150+0000] {connection_wrapper.py:334} INFO - AWS Connection (conn_id='minio_s3', conn_type='aws') credentials retrieved from login and password.
[2025-04-04T10:23:23.820+0000] {base.py:73} INFO - Using connection ID 'minio_s3' for task execution.
[2025-04-04T10:23:23.888+0000] {connection_wrapper.py:334} INFO - AWS Connection (conn_id='minio_s3', conn_type='aws') credentials retrieved from login and password.
[2025-04-04T10:23:28.382+0000] {base.py:73} INFO - Using connection ID 'minio_s3' for task execution.
[2025-04-04T10:23:28.393+0000] {connection_wrapper.py:334} INFO - AWS Connection (conn_id='minio_s3', conn_type='aws') credentials retrieved from login and password.
[2025-04-04T10:23:37.780+0000] {base.py:73} INFO - Using connection ID 'minio_s3' for task execution.
[2025-04-04T10:23:37.802+0000] {connection_wrapper.py:334} INFO - AWS Connection (conn_id='minio_s3', conn_type='aws') credentials retrieved from login and password.
[2025-04-04T10:23:42.201+0000] {base.py:73} INFO - Using connection ID 'minio_s3' for task execution.
[2025-04-04T10:23:42.203+0000] {connection_wrapper.py:334} INFO - AWS Connection (conn_id='minio_s3', conn_type='aws') credentials retrieved from login and password.
[2025-04-04T10:23:49.330+0000] {base.py:73} INFO - Using connection ID 'minio_s3' for task execution.
[2025-04-04T10:23:49.335+0000] {connection_wrapper.py:334} INFO - AWS Connection (conn_id='minio_s3', conn_type='aws') credentials retrieved from login and password.
[2025-04-04T10:23:59.169+0000] {base.py:73} INFO - Using connection ID 'minio_s3' for task execution.
[2025-04-04T10:23:59.180+0000] {connection_wrapper.py:334} INFO - AWS Connection (conn_id='minio_s3', conn_type='aws') credentials retrieved from login and password.
[2025-04-04T10:24:08.079+0000] {base.py:73} INFO - Using connection ID 'minio_s3' for task execution.
[2025-04-04T10:24:08.139+0000] {connection_wrapper.py:334} INFO - AWS Connection (conn_id='minio_s3', conn_type='aws') credentials retrieved from login and password.
[2025-04-04T10:24:15.463+0000] {base.py:73} INFO - Using connection ID 'minio_s3' for task execution.
[2025-04-04T10:24:15.566+0000] {connection_wrapper.py:334} INFO - AWS Connection (conn_id='minio_s3', conn_type='aws') credentials retrieved from login and password.
[2025-04-04T10:24:29.274+0000] {base.py:73} INFO - Using connection ID 'minio_s3' for task execution.
[2025-04-04T10:24:29.296+0000] {connection_wrapper.py:334} INFO - AWS Connection (conn_id='minio_s3', conn_type='aws') credentials retrieved from login and password.
[2025-04-04T10:24:41.351+0000] {base.py:73} INFO - Using connection ID 'minio_s3' for task execution.
[2025-04-04T10:24:41.365+0000] {connection_wrapper.py:334} INFO - AWS Connection (conn_id='minio_s3', conn_type='aws') credentials retrieved from login and password.
[2025-04-04T10:24:59.190+0000] {base.py:73} INFO - Using connection ID 'minio_s3' for task execution.
[2025-04-04T10:24:59.207+0000] {connection_wrapper.py:334} INFO - AWS Connection (conn_id='minio_s3', conn_type='aws') credentials retrieved from login and password.
[2025-04-04T10:26:53.322+0000] {base.py:73} INFO - Using connection ID 'minio_s3' for task execution.
[2025-04-04T10:26:53.399+0000] {connection_wrapper.py:334} INFO - AWS Connection (conn_id='minio_s3', conn_type='aws') credentials retrieved from login and password.
[2025-04-04T10:27:10.387+0000] {base.py:73} INFO - Using connection ID 'minio_s3' for task execution.
[2025-04-04T10:27:10.388+0000] {connection_wrapper.py:334} INFO - AWS Connection (conn_id='minio_s3', conn_type='aws') credentials retrieved from login and password.
[2025-04-04T10:27:23.201+0000] {base.py:73} INFO - Using connection ID 'minio_s3' for task execution.
[2025-04-04T10:27:23.281+0000] {connection_wrapper.py:334} INFO - AWS Connection (conn_id='minio_s3', conn_type='aws') credentials retrieved from login and password.
[2025-04-04T10:27:33.136+0000] {base.py:73} INFO - Using connection ID 'minio_s3' for task execution.
[2025-04-04T10:27:33.144+0000] {connection_wrapper.py:334} INFO - AWS Connection (conn_id='minio_s3', conn_type='aws') credentials retrieved from login and password.
[2025-04-04T10:27:45.206+0000] {base.py:73} INFO - Using connection ID 'minio_s3' for task execution.
[2025-04-04T10:27:45.256+0000] {connection_wrapper.py:334} INFO - AWS Connection (conn_id='minio_s3', conn_type='aws') credentials retrieved from login and password.
[2025-04-04T10:27:59.805+0000] {base.py:73} INFO - Using connection ID 'minio_s3' for task execution.
[2025-04-04T10:27:59.859+0000] {connection_wrapper.py:334} INFO - AWS Connection (conn_id='minio_s3', conn_type='aws') credentials retrieved from login and password.
[2025-04-04T10:28:14.469+0000] {base.py:73} INFO - Using connection ID 'minio_s3' for task execution.
[2025-04-04T10:28:14.568+0000] {connection_wrapper.py:334} INFO - AWS Connection (conn_id='minio_s3', conn_type='aws') credentials retrieved from login and password.
[2025-04-04T10:28:27.530+0000] {base.py:73} INFO - Using connection ID 'minio_s3' for task execution.
[2025-04-04T10:28:27.538+0000] {connection_wrapper.py:334} INFO - AWS Connection (conn_id='minio_s3', conn_type='aws') credentials retrieved from login and password.
[2025-04-04T10:28:43.090+0000] {base.py:73} INFO - Using connection ID 'minio_s3' for task execution.
[2025-04-04T10:28:43.118+0000] {connection_wrapper.py:334} INFO - AWS Connection (conn_id='minio_s3', conn_type='aws') credentials retrieved from login and password.
[2025-04-04T10:30:57.805+0000] {base.py:73} INFO - Using connection ID 'minio_s3' for task execution.
[2025-04-04T10:30:57.881+0000] {connection_wrapper.py:334} INFO - AWS Connection (conn_id='minio_s3', conn_type='aws') credentials retrieved from login and password.
[2025-04-04T10:31:30.074+0000] {base.py:73} INFO - Using connection ID 'minio_s3' for task execution.
[2025-04-04T10:31:30.149+0000] {connection_wrapper.py:334} INFO - AWS Connection (conn_id='minio_s3', conn_type='aws') credentials retrieved from login and password.
[2025-04-04T10:32:01.637+0000] {base.py:73} INFO - Using connection ID 'minio_s3' for task execution.
[2025-04-04T10:32:01.831+0000] {connection_wrapper.py:334} INFO - AWS Connection (conn_id='minio_s3', conn_type='aws') credentials retrieved from login and password.
[2025-04-04T10:33:26.596+0000] {base_job.py:243} ERROR - LocalTaskJob heartbeat got an exception
Traceback (most recent call last):
  File "/home/airflow/.local/lib/python3.7/site-packages/sqlalchemy/engine/base.py", line 3361, in _wrap_pool_connect
    return fn()
  File "/home/airflow/.local/lib/python3.7/site-packages/sqlalchemy/pool/base.py", line 327, in connect
    return _ConnectionFairy._checkout(self)
  File "/home/airflow/.local/lib/python3.7/site-packages/sqlalchemy/pool/base.py", line 894, in _checkout
    fairy = _ConnectionRecord.checkout(pool)
  File "/home/airflow/.local/lib/python3.7/site-packages/sqlalchemy/pool/base.py", line 493, in checkout
    rec = pool._do_get()
  File "/home/airflow/.local/lib/python3.7/site-packages/sqlalchemy/pool/impl.py", line 256, in _do_get
    return self._create_connection()
  File "/home/airflow/.local/lib/python3.7/site-packages/sqlalchemy/pool/base.py", line 273, in _create_connection
    return _ConnectionRecord(self)
  File "/home/airflow/.local/lib/python3.7/site-packages/sqlalchemy/pool/base.py", line 388, in __init__
    self.__connect()
  File "/home/airflow/.local/lib/python3.7/site-packages/sqlalchemy/pool/base.py", line 691, in __connect
    pool.logger.debug("Error on connect(): %s", e)
  File "/home/airflow/.local/lib/python3.7/site-packages/sqlalchemy/util/langhelpers.py", line 72, in __exit__
    with_traceback=exc_tb,
  File "/home/airflow/.local/lib/python3.7/site-packages/sqlalchemy/util/compat.py", line 211, in raise_
    raise exception
  File "/home/airflow/.local/lib/python3.7/site-packages/sqlalchemy/pool/base.py", line 686, in __connect
    self.dbapi_connection = connection = pool._invoke_creator(self)
  File "/home/airflow/.local/lib/python3.7/site-packages/sqlalchemy/engine/create.py", line 578, in connect
    return dialect.connect(*cargs, **cparams)
  File "/home/airflow/.local/lib/python3.7/site-packages/sqlalchemy/engine/default.py", line 598, in connect
    return self.dbapi.connect(*cargs, **cparams)
  File "/home/airflow/.local/lib/python3.7/site-packages/psycopg2/__init__.py", line 122, in connect
    conn = _connect(dsn, connection_factory=connection_factory, **kwasync)
psycopg2.OperationalError: could not translate host name "postgres" to address: Temporary failure in name resolution


The above exception was the direct cause of the following exception:

Traceback (most recent call last):
  File "/home/airflow/.local/lib/python3.7/site-packages/airflow/jobs/base_job.py", line 239, in heartbeat
    self.heartbeat_callback(session=session)
  File "/home/airflow/.local/lib/python3.7/site-packages/airflow/utils/session.py", line 72, in wrapper
    return func(*args, **kwargs)
  File "/home/airflow/.local/lib/python3.7/site-packages/airflow/jobs/local_task_job.py", line 227, in heartbeat_callback
    self.task_instance.refresh_from_db()
  File "/home/airflow/.local/lib/python3.7/site-packages/airflow/utils/session.py", line 75, in wrapper
    return func(*args, session=session, **kwargs)
  File "/home/airflow/.local/lib/python3.7/site-packages/airflow/models/taskinstance.py", line 791, in refresh_from_db
    ti = qry.one_or_none()
  File "/home/airflow/.local/lib/python3.7/site-packages/sqlalchemy/orm/query.py", line 2850, in one_or_none
    return self._iter().one_or_none()
  File "/home/airflow/.local/lib/python3.7/site-packages/sqlalchemy/orm/query.py", line 2919, in _iter
    execution_options={"_sa_orm_load_options": self.load_options},
  File "/home/airflow/.local/lib/python3.7/site-packages/sqlalchemy/orm/session.py", line 1713, in execute
    conn = self._connection_for_bind(bind)
  File "/home/airflow/.local/lib/python3.7/site-packages/sqlalchemy/orm/session.py", line 1553, in _connection_for_bind
    engine, execution_options
  File "/home/airflow/.local/lib/python3.7/site-packages/sqlalchemy/orm/session.py", line 747, in _connection_for_bind
    conn = bind.connect()
  File "/home/airflow/.local/lib/python3.7/site-packages/sqlalchemy/engine/base.py", line 3315, in connect
    return self._connection_cls(self, close_with_result=close_with_result)
  File "/home/airflow/.local/lib/python3.7/site-packages/sqlalchemy/engine/base.py", line 96, in __init__
    else engine.raw_connection()
  File "/home/airflow/.local/lib/python3.7/site-packages/sqlalchemy/engine/base.py", line 3394, in raw_connection
    return self._wrap_pool_connect(self.pool.connect, _connection)
  File "/home/airflow/.local/lib/python3.7/site-packages/sqlalchemy/engine/base.py", line 3365, in _wrap_pool_connect
    e, dialect, self
  File "/home/airflow/.local/lib/python3.7/site-packages/sqlalchemy/engine/base.py", line 2199, in _handle_dbapi_exception_noconnection
    sqlalchemy_exception, with_traceback=exc_info[2], from_=e
  File "/home/airflow/.local/lib/python3.7/site-packages/sqlalchemy/util/compat.py", line 211, in raise_
    raise exception
  File "/home/airflow/.local/lib/python3.7/site-packages/sqlalchemy/engine/base.py", line 3361, in _wrap_pool_connect
    return fn()
  File "/home/airflow/.local/lib/python3.7/site-packages/sqlalchemy/pool/base.py", line 327, in connect
    return _ConnectionFairy._checkout(self)
  File "/home/airflow/.local/lib/python3.7/site-packages/sqlalchemy/pool/base.py", line 894, in _checkout
    fairy = _ConnectionRecord.checkout(pool)
  File "/home/airflow/.local/lib/python3.7/site-packages/sqlalchemy/pool/base.py", line 493, in checkout
    rec = pool._do_get()
  File "/home/airflow/.local/lib/python3.7/site-packages/sqlalchemy/pool/impl.py", line 256, in _do_get
    return self._create_connection()
  File "/home/airflow/.local/lib/python3.7/site-packages/sqlalchemy/pool/base.py", line 273, in _create_connection
    return _ConnectionRecord(self)
  File "/home/airflow/.local/lib/python3.7/site-packages/sqlalchemy/pool/base.py", line 388, in __init__
    self.__connect()
  File "/home/airflow/.local/lib/python3.7/site-packages/sqlalchemy/pool/base.py", line 691, in __connect
    pool.logger.debug("Error on connect(): %s", e)
  File "/home/airflow/.local/lib/python3.7/site-packages/sqlalchemy/util/langhelpers.py", line 72, in __exit__
    with_traceback=exc_tb,
  File "/home/airflow/.local/lib/python3.7/site-packages/sqlalchemy/util/compat.py", line 211, in raise_
    raise exception
  File "/home/airflow/.local/lib/python3.7/site-packages/sqlalchemy/pool/base.py", line 686, in __connect
    self.dbapi_connection = connection = pool._invoke_creator(self)
  File "/home/airflow/.local/lib/python3.7/site-packages/sqlalchemy/engine/create.py", line 578, in connect
    return dialect.connect(*cargs, **cparams)
  File "/home/airflow/.local/lib/python3.7/site-packages/sqlalchemy/engine/default.py", line 598, in connect
    return self.dbapi.connect(*cargs, **cparams)
  File "/home/airflow/.local/lib/python3.7/site-packages/psycopg2/__init__.py", line 122, in connect
    conn = _connect(dsn, connection_factory=connection_factory, **kwasync)
sqlalchemy.exc.OperationalError: (psycopg2.OperationalError) could not translate host name "postgres" to address: Temporary failure in name resolution

(Background on this error at: https://sqlalche.me/e/14/e3q8)
[2025-04-04T10:34:04.250+0000] {base_job.py:243} ERROR - LocalTaskJob heartbeat got an exception
Traceback (most recent call last):
  File "/home/airflow/.local/lib/python3.7/site-packages/sqlalchemy/engine/base.py", line 3361, in _wrap_pool_connect
    return fn()
  File "/home/airflow/.local/lib/python3.7/site-packages/sqlalchemy/pool/base.py", line 327, in connect
    return _ConnectionFairy._checkout(self)
  File "/home/airflow/.local/lib/python3.7/site-packages/sqlalchemy/pool/base.py", line 894, in _checkout
    fairy = _ConnectionRecord.checkout(pool)
  File "/home/airflow/.local/lib/python3.7/site-packages/sqlalchemy/pool/base.py", line 493, in checkout
    rec = pool._do_get()
  File "/home/airflow/.local/lib/python3.7/site-packages/sqlalchemy/pool/impl.py", line 256, in _do_get
    return self._create_connection()
  File "/home/airflow/.local/lib/python3.7/site-packages/sqlalchemy/pool/base.py", line 273, in _create_connection
    return _ConnectionRecord(self)
  File "/home/airflow/.local/lib/python3.7/site-packages/sqlalchemy/pool/base.py", line 388, in __init__
    self.__connect()
  File "/home/airflow/.local/lib/python3.7/site-packages/sqlalchemy/pool/base.py", line 691, in __connect
    pool.logger.debug("Error on connect(): %s", e)
  File "/home/airflow/.local/lib/python3.7/site-packages/sqlalchemy/util/langhelpers.py", line 72, in __exit__
    with_traceback=exc_tb,
  File "/home/airflow/.local/lib/python3.7/site-packages/sqlalchemy/util/compat.py", line 211, in raise_
    raise exception
  File "/home/airflow/.local/lib/python3.7/site-packages/sqlalchemy/pool/base.py", line 686, in __connect
    self.dbapi_connection = connection = pool._invoke_creator(self)
  File "/home/airflow/.local/lib/python3.7/site-packages/sqlalchemy/engine/create.py", line 578, in connect
    return dialect.connect(*cargs, **cparams)
  File "/home/airflow/.local/lib/python3.7/site-packages/sqlalchemy/engine/default.py", line 598, in connect
    return self.dbapi.connect(*cargs, **cparams)
  File "/home/airflow/.local/lib/python3.7/site-packages/psycopg2/__init__.py", line 122, in connect
    conn = _connect(dsn, connection_factory=connection_factory, **kwasync)
psycopg2.OperationalError: could not translate host name "postgres" to address: Temporary failure in name resolution


The above exception was the direct cause of the following exception:

Traceback (most recent call last):
  File "/home/airflow/.local/lib/python3.7/site-packages/airflow/jobs/base_job.py", line 215, in heartbeat
    session.merge(self)
  File "/home/airflow/.local/lib/python3.7/site-packages/sqlalchemy/orm/session.py", line 3057, in merge
    _resolve_conflict_map=_resolve_conflict_map,
  File "/home/airflow/.local/lib/python3.7/site-packages/sqlalchemy/orm/session.py", line 3135, in _merge
    options=options,
  File "/home/airflow/.local/lib/python3.7/site-packages/sqlalchemy/orm/session.py", line 2856, in get
    execution_options=execution_options,
  File "/home/airflow/.local/lib/python3.7/site-packages/sqlalchemy/orm/session.py", line 2974, in _get_impl
    load_options=load_options,
  File "/home/airflow/.local/lib/python3.7/site-packages/sqlalchemy/orm/loading.py", line 534, in load_on_pk_identity
    bind_arguments=bind_arguments,
  File "/home/airflow/.local/lib/python3.7/site-packages/sqlalchemy/orm/session.py", line 1713, in execute
    conn = self._connection_for_bind(bind)
  File "/home/airflow/.local/lib/python3.7/site-packages/sqlalchemy/orm/session.py", line 1553, in _connection_for_bind
    engine, execution_options
  File "/home/airflow/.local/lib/python3.7/site-packages/sqlalchemy/orm/session.py", line 747, in _connection_for_bind
    conn = bind.connect()
  File "/home/airflow/.local/lib/python3.7/site-packages/sqlalchemy/engine/base.py", line 3315, in connect
    return self._connection_cls(self, close_with_result=close_with_result)
  File "/home/airflow/.local/lib/python3.7/site-packages/sqlalchemy/engine/base.py", line 96, in __init__
    else engine.raw_connection()
  File "/home/airflow/.local/lib/python3.7/site-packages/sqlalchemy/engine/base.py", line 3394, in raw_connection
    return self._wrap_pool_connect(self.pool.connect, _connection)
  File "/home/airflow/.local/lib/python3.7/site-packages/sqlalchemy/engine/base.py", line 3365, in _wrap_pool_connect
    e, dialect, self
  File "/home/airflow/.local/lib/python3.7/site-packages/sqlalchemy/engine/base.py", line 2199, in _handle_dbapi_exception_noconnection
    sqlalchemy_exception, with_traceback=exc_info[2], from_=e
  File "/home/airflow/.local/lib/python3.7/site-packages/sqlalchemy/util/compat.py", line 211, in raise_
    raise exception
  File "/home/airflow/.local/lib/python3.7/site-packages/sqlalchemy/engine/base.py", line 3361, in _wrap_pool_connect
    return fn()
  File "/home/airflow/.local/lib/python3.7/site-packages/sqlalchemy/pool/base.py", line 327, in connect
    return _ConnectionFairy._checkout(self)
  File "/home/airflow/.local/lib/python3.7/site-packages/sqlalchemy/pool/base.py", line 894, in _checkout
    fairy = _ConnectionRecord.checkout(pool)
  File "/home/airflow/.local/lib/python3.7/site-packages/sqlalchemy/pool/base.py", line 493, in checkout
    rec = pool._do_get()
  File "/home/airflow/.local/lib/python3.7/site-packages/sqlalchemy/pool/impl.py", line 256, in _do_get
    return self._create_connection()
  File "/home/airflow/.local/lib/python3.7/site-packages/sqlalchemy/pool/base.py", line 273, in _create_connection
    return _ConnectionRecord(self)
  File "/home/airflow/.local/lib/python3.7/site-packages/sqlalchemy/pool/base.py", line 388, in __init__
    self.__connect()
  File "/home/airflow/.local/lib/python3.7/site-packages/sqlalchemy/pool/base.py", line 691, in __connect
    pool.logger.debug("Error on connect(): %s", e)
  File "/home/airflow/.local/lib/python3.7/site-packages/sqlalchemy/util/langhelpers.py", line 72, in __exit__
    with_traceback=exc_tb,
  File "/home/airflow/.local/lib/python3.7/site-packages/sqlalchemy/util/compat.py", line 211, in raise_
    raise exception
  File "/home/airflow/.local/lib/python3.7/site-packages/sqlalchemy/pool/base.py", line 686, in __connect
    self.dbapi_connection = connection = pool._invoke_creator(self)
  File "/home/airflow/.local/lib/python3.7/site-packages/sqlalchemy/engine/create.py", line 578, in connect
    return dialect.connect(*cargs, **cparams)
  File "/home/airflow/.local/lib/python3.7/site-packages/sqlalchemy/engine/default.py", line 598, in connect
    return self.dbapi.connect(*cargs, **cparams)
  File "/home/airflow/.local/lib/python3.7/site-packages/psycopg2/__init__.py", line 122, in connect
    conn = _connect(dsn, connection_factory=connection_factory, **kwasync)
sqlalchemy.exc.OperationalError: (psycopg2.OperationalError) could not translate host name "postgres" to address: Temporary failure in name resolution

(Background on this error at: https://sqlalche.me/e/14/e3q8)
[2025-04-04T10:34:38.319+0000] {base.py:73} INFO - Using connection ID 'minio_s3' for task execution.
[2025-04-04T10:34:38.352+0000] {connection_wrapper.py:334} INFO - AWS Connection (conn_id='minio_s3', conn_type='aws') credentials retrieved from login and password.
[2025-04-04T10:34:49.665+0000] {base.py:73} INFO - Using connection ID 'minio_s3' for task execution.
[2025-04-04T10:34:49.675+0000] {connection_wrapper.py:334} INFO - AWS Connection (conn_id='minio_s3', conn_type='aws') credentials retrieved from login and password.
[2025-04-04T10:34:55.923+0000] {base.py:73} INFO - Using connection ID 'minio_s3' for task execution.
[2025-04-04T10:34:55.935+0000] {connection_wrapper.py:334} INFO - AWS Connection (conn_id='minio_s3', conn_type='aws') credentials retrieved from login and password.
[2025-04-04T10:35:02.945+0000] {base.py:73} INFO - Using connection ID 'minio_s3' for task execution.
[2025-04-04T10:35:02.983+0000] {connection_wrapper.py:334} INFO - AWS Connection (conn_id='minio_s3', conn_type='aws') credentials retrieved from login and password.
[2025-04-04T10:35:07.664+0000] {base.py:73} INFO - Using connection ID 'minio_s3' for task execution.
[2025-04-04T10:35:07.670+0000] {connection_wrapper.py:334} INFO - AWS Connection (conn_id='minio_s3', conn_type='aws') credentials retrieved from login and password.
[2025-04-04T10:35:12.492+0000] {base.py:73} INFO - Using connection ID 'minio_s3' for task execution.
[2025-04-04T10:35:12.497+0000] {connection_wrapper.py:334} INFO - AWS Connection (conn_id='minio_s3', conn_type='aws') credentials retrieved from login and password.
[2025-04-04T10:35:49.174+0000] {base.py:73} INFO - Using connection ID 'minio_s3' for task execution.
[2025-04-04T10:35:49.184+0000] {connection_wrapper.py:334} INFO - AWS Connection (conn_id='minio_s3', conn_type='aws') credentials retrieved from login and password.
[2025-04-04T10:35:55.225+0000] {base.py:73} INFO - Using connection ID 'minio_s3' for task execution.
[2025-04-04T10:35:55.228+0000] {connection_wrapper.py:334} INFO - AWS Connection (conn_id='minio_s3', conn_type='aws') credentials retrieved from login and password.
[2025-04-04T10:36:02.842+0000] {local_task_job.py:112} ERROR - Received SIGTERM. Terminating subprocesses
[2025-04-04T10:36:03.503+0000] {process_utils.py:133} INFO - Sending Signals.SIGTERM to group 96. PIDs of all processes in the group: [96]
[2025-04-04T10:36:03.539+0000] {process_utils.py:84} INFO - Sending the signal Signals.SIGTERM to group 96
[2025-04-04T10:36:05.700+0000] {taskinstance.py:1479} ERROR - Received SIGTERM. Terminating subprocesses.
[2025-04-04T10:36:05.894+0000] {taskinstance.py:1768} ERROR - Task failed with exception
Traceback (most recent call last):
  File "/home/airflow/.local/lib/python3.7/site-packages/airflow/operators/python.py", line 175, in execute
    return_value = self.execute_callable()
  File "/home/airflow/.local/lib/python3.7/site-packages/airflow/operators/python.py", line 192, in execute_callable
    return self.python_callable(*self.op_args, **self.op_kwargs)
  File "/opt/airflow/dags/dag_data_collect.py", line 85, in download_and_upload_images
    if not check_image_in_s3(new_image_name):
  File "/opt/airflow/dags/dag_data_collect.py", line 55, in check_image_in_s3
    return s3.check_for_key(key, bucket_name)
  File "/home/airflow/.local/lib/python3.7/site-packages/airflow/providers/amazon/aws/hooks/s3.py", line 99, in wrapper
    return func(*bound_args.args, **bound_args.kwargs)
  File "/home/airflow/.local/lib/python3.7/site-packages/airflow/providers/amazon/aws/hooks/s3.py", line 70, in wrapper
    return func(*bound_args.args, **bound_args.kwargs)
  File "/home/airflow/.local/lib/python3.7/site-packages/airflow/providers/amazon/aws/hooks/s3.py", line 481, in check_for_key
    obj = self.head_object(key, bucket_name)
  File "/home/airflow/.local/lib/python3.7/site-packages/airflow/providers/amazon/aws/hooks/s3.py", line 99, in wrapper
    return func(*bound_args.args, **bound_args.kwargs)
  File "/home/airflow/.local/lib/python3.7/site-packages/airflow/providers/amazon/aws/hooks/s3.py", line 70, in wrapper
    return func(*bound_args.args, **bound_args.kwargs)
  File "/home/airflow/.local/lib/python3.7/site-packages/airflow/providers/amazon/aws/hooks/s3.py", line 464, in head_object
    return self.get_conn().head_object(Bucket=bucket_name, Key=key)
  File "/home/airflow/.local/lib/python3.7/site-packages/airflow/providers/amazon/aws/hooks/base_aws.py", line 641, in get_conn
    return self.conn
  File "/home/airflow/.local/lib/python3.7/site-packages/cached_property.py", line 36, in __get__
    value = obj.__dict__[self.func.__name__] = self.func(obj)
  File "/home/airflow/.local/lib/python3.7/site-packages/airflow/providers/amazon/aws/hooks/base_aws.py", line 609, in conn
    return self.get_client_type(region_name=self.region_name)
  File "/home/airflow/.local/lib/python3.7/site-packages/airflow/providers/amazon/aws/hooks/base_aws.py", line 578, in get_client_type
    verify=self.verify,
  File "/home/airflow/.local/lib/python3.7/site-packages/boto3/session.py", line 309, in client
    config=config,
  File "/home/airflow/.local/lib/python3.7/site-packages/botocore/session.py", line 953, in create_client
    endpoint_resolver = self._get_internal_component('endpoint_resolver')
  File "/home/airflow/.local/lib/python3.7/site-packages/botocore/session.py", line 812, in _get_internal_component
    return self._internal_components.get_component(name)
  File "/home/airflow/.local/lib/python3.7/site-packages/botocore/session.py", line 1108, in get_component
    self._components[name] = factory()
  File "/home/airflow/.local/lib/python3.7/site-packages/botocore/session.py", line 199, in create_default_resolver
    endpoints, path = loader.load_data_with_path('endpoints')
  File "/home/airflow/.local/lib/python3.7/site-packages/botocore/loaders.py", line 142, in _wrapper
    data = func(self, *args, **kwargs)
  File "/home/airflow/.local/lib/python3.7/site-packages/botocore/loaders.py", line 448, in load_data_with_path
    found = self.file_loader.load_file(possible_path)
  File "/home/airflow/.local/lib/python3.7/site-packages/botocore/loaders.py", line 194, in load_file
    data = self._load_file(file_path + ext, open_method)
  File "/home/airflow/.local/lib/python3.7/site-packages/botocore/loaders.py", line 181, in _load_file
    return json.loads(payload, object_pairs_hook=OrderedDict)
  File "/usr/local/lib/python3.7/json/__init__.py", line 361, in loads
    return cls(**kw).decode(s)
  File "/usr/local/lib/python3.7/json/decoder.py", line 337, in decode
    obj, end = self.raw_decode(s, idx=_w(s, 0).end())
  File "/usr/local/lib/python3.7/json/decoder.py", line 353, in raw_decode
    obj, end = self.scan_once(s, idx)
  File "/home/airflow/.local/lib/python3.7/site-packages/airflow/models/taskinstance.py", line 1481, in signal_handler
    raise AirflowException("Task received SIGTERM signal")
airflow.exceptions.AirflowException: Task received SIGTERM signal
[2025-04-04T10:36:05.960+0000] {taskinstance.py:1323} INFO - Marking task as UP_FOR_RETRY. dag_id=download_and_store_images, task_id=download_and_upload_images, execution_date=20240201T000000, start_date=20250404T101943, end_date=20250404T103605
[2025-04-04T10:36:06.414+0000] {standard_task_runner.py:105} ERROR - Failed to execute job 782 for task download_and_upload_images (Task received SIGTERM signal; 96)
[2025-04-04T10:36:06.696+0000] {process_utils.py:79} INFO - Process psutil.Process(pid=96, status='terminated', exitcode=1, started='10:19:43') (96) terminated with exit code 1
[2025-04-04T10:36:07.481+0000] {local_task_job.py:208} INFO - Task exited with return code 143
