[2025-04-04T15:12:15.435+0000] {taskinstance.py:1083} INFO - Dependencies all met for <TaskInstance: download_and_store_images.download_and_upload_images scheduled__2025-04-03T15:11:02.216079+00:00 [queued]>
[2025-04-04T15:12:15.701+0000] {taskinstance.py:1083} INFO - Dependencies all met for <TaskInstance: download_and_store_images.download_and_upload_images scheduled__2025-04-03T15:11:02.216079+00:00 [queued]>
[2025-04-04T15:12:15.718+0000] {taskinstance.py:1279} INFO - 
--------------------------------------------------------------------------------
[2025-04-04T15:12:15.720+0000] {taskinstance.py:1280} INFO - Starting attempt 1 of 2
[2025-04-04T15:12:15.725+0000] {taskinstance.py:1281} INFO - 
--------------------------------------------------------------------------------
[2025-04-04T15:12:16.020+0000] {taskinstance.py:1300} INFO - Executing <Task(PythonOperator): download_and_upload_images> on 2025-04-03 15:11:02.216079+00:00
[2025-04-04T15:12:16.071+0000] {standard_task_runner.py:55} INFO - Started process 109 to run task
[2025-04-04T15:12:16.122+0000] {standard_task_runner.py:82} INFO - Running: ['***', 'tasks', 'run', 'download_and_store_images', 'download_and_upload_images', 'scheduled__2025-04-03T15:11:02.216079+00:00', '--job-id', '813', '--raw', '--subdir', 'DAGS_FOLDER/dag_data_collect.py', '--cfg-path', '/tmp/tmp_s5qr1e1']
[2025-04-04T15:12:16.129+0000] {standard_task_runner.py:83} INFO - Job 813: Subtask download_and_upload_images
[2025-04-04T15:12:16.495+0000] {warnings.py:110} WARNING - /home/***/.local/lib/python3.7/site-packages/***/settings.py:249: DeprecationWarning: The sql_alchemy_conn option in [core] has been moved to the sql_alchemy_conn option in [database] - the old setting has been used, but please update your config.
  SQL_ALCHEMY_CONN = conf.get("database", "SQL_ALCHEMY_CONN")

[2025-04-04T15:12:16.985+0000] {warnings.py:110} WARNING - /home/***/.local/lib/python3.7/site-packages/***/utils/sqlalchemy.py:124: DeprecationWarning: The sql_alchemy_conn option in [core] has been moved to the sql_alchemy_conn option in [database] - the old setting has been used, but please update your config.
  return not conf.get("database", "sql_alchemy_conn").startswith("mssql")

[2025-04-04T15:12:17.322+0000] {task_command.py:388} INFO - Running <TaskInstance: download_and_store_images.download_and_upload_images scheduled__2025-04-03T15:11:02.216079+00:00 [running]> on host fd5deae9c635
[2025-04-04T15:12:18.621+0000] {taskinstance.py:1509} INFO - Exporting the following env vars:
AIRFLOW_CTX_DAG_OWNER=***
AIRFLOW_CTX_DAG_ID=download_and_store_images
AIRFLOW_CTX_TASK_ID=download_and_upload_images
AIRFLOW_CTX_EXECUTION_DATE=2025-04-03T15:11:02.216079+00:00
AIRFLOW_CTX_TRY_NUMBER=1
AIRFLOW_CTX_DAG_RUN_ID=scheduled__2025-04-03T15:11:02.216079+00:00
[2025-04-04T15:12:22.741+0000] {base.py:73} INFO - Using connection ID 'minio_s3' for task execution.
[2025-04-04T15:12:22.746+0000] {connection_wrapper.py:334} INFO - AWS Connection (conn_id='minio_s3', conn_type='aws') credentials retrieved from login and password.
[2025-04-04T15:12:22.750+0000] {warnings.py:110} WARNING - /home/***/.local/lib/python3.7/site-packages/***/providers/amazon/aws/utils/connection_wrapper.py:8: DeprecationWarning: extra['host'] is deprecated and will be removed in a future release. Please set extra['endpoint_url'] instead
  #

[2025-04-04T15:13:00.876+0000] {base.py:73} INFO - Using connection ID 'minio_s3' for task execution.
[2025-04-04T15:13:00.886+0000] {connection_wrapper.py:334} INFO - AWS Connection (conn_id='minio_s3', conn_type='aws') credentials retrieved from login and password.
[2025-04-04T15:13:17.236+0000] {base.py:73} INFO - Using connection ID 'minio_s3' for task execution.
[2025-04-04T15:13:17.275+0000] {connection_wrapper.py:334} INFO - AWS Connection (conn_id='minio_s3', conn_type='aws') credentials retrieved from login and password.
[2025-04-04T15:13:22.528+0000] {base.py:73} INFO - Using connection ID 'minio_s3' for task execution.
[2025-04-04T15:13:22.532+0000] {connection_wrapper.py:334} INFO - AWS Connection (conn_id='minio_s3', conn_type='aws') credentials retrieved from login and password.
[2025-04-04T15:13:27.870+0000] {base.py:73} INFO - Using connection ID 'minio_s3' for task execution.
[2025-04-04T15:13:27.885+0000] {connection_wrapper.py:334} INFO - AWS Connection (conn_id='minio_s3', conn_type='aws') credentials retrieved from login and password.
[2025-04-04T15:13:34.005+0000] {base.py:73} INFO - Using connection ID 'minio_s3' for task execution.
[2025-04-04T15:13:34.007+0000] {connection_wrapper.py:334} INFO - AWS Connection (conn_id='minio_s3', conn_type='aws') credentials retrieved from login and password.
[2025-04-04T15:13:42.146+0000] {base.py:73} INFO - Using connection ID 'minio_s3' for task execution.
[2025-04-04T15:13:42.197+0000] {connection_wrapper.py:334} INFO - AWS Connection (conn_id='minio_s3', conn_type='aws') credentials retrieved from login and password.
[2025-04-04T15:13:53.694+0000] {base.py:73} INFO - Using connection ID 'minio_s3' for task execution.
[2025-04-04T15:13:53.697+0000] {connection_wrapper.py:334} INFO - AWS Connection (conn_id='minio_s3', conn_type='aws') credentials retrieved from login and password.
[2025-04-04T15:14:07.715+0000] {base.py:73} INFO - Using connection ID 'minio_s3' for task execution.
[2025-04-04T15:14:07.756+0000] {connection_wrapper.py:334} INFO - AWS Connection (conn_id='minio_s3', conn_type='aws') credentials retrieved from login and password.
[2025-04-04T15:14:44.792+0000] {base.py:73} INFO - Using connection ID 'minio_s3' for task execution.
[2025-04-04T15:14:44.989+0000] {connection_wrapper.py:334} INFO - AWS Connection (conn_id='minio_s3', conn_type='aws') credentials retrieved from login and password.
[2025-04-04T15:16:44.709+0000] {base.py:73} INFO - Using connection ID 'minio_s3' for task execution.
[2025-04-04T15:16:44.957+0000] {connection_wrapper.py:334} INFO - AWS Connection (conn_id='minio_s3', conn_type='aws') credentials retrieved from login and password.
[2025-04-04T15:19:12.830+0000] {base.py:73} INFO - Using connection ID 'minio_s3' for task execution.
[2025-04-04T15:19:12.914+0000] {connection_wrapper.py:334} INFO - AWS Connection (conn_id='minio_s3', conn_type='aws') credentials retrieved from login and password.
[2025-04-04T15:19:18.554+0000] {base.py:73} INFO - Using connection ID 'minio_s3' for task execution.
[2025-04-04T15:19:18.614+0000] {connection_wrapper.py:334} INFO - AWS Connection (conn_id='minio_s3', conn_type='aws') credentials retrieved from login and password.
[2025-04-04T15:19:27.240+0000] {base.py:73} INFO - Using connection ID 'minio_s3' for task execution.
[2025-04-04T15:19:27.243+0000] {connection_wrapper.py:334} INFO - AWS Connection (conn_id='minio_s3', conn_type='aws') credentials retrieved from login and password.
[2025-04-04T15:19:34.287+0000] {base.py:73} INFO - Using connection ID 'minio_s3' for task execution.
[2025-04-04T15:19:34.288+0000] {connection_wrapper.py:334} INFO - AWS Connection (conn_id='minio_s3', conn_type='aws') credentials retrieved from login and password.
[2025-04-04T15:19:37.810+0000] {base.py:73} INFO - Using connection ID 'minio_s3' for task execution.
[2025-04-04T15:19:37.812+0000] {connection_wrapper.py:334} INFO - AWS Connection (conn_id='minio_s3', conn_type='aws') credentials retrieved from login and password.
[2025-04-04T15:19:43.908+0000] {base.py:73} INFO - Using connection ID 'minio_s3' for task execution.
[2025-04-04T15:19:43.910+0000] {connection_wrapper.py:334} INFO - AWS Connection (conn_id='minio_s3', conn_type='aws') credentials retrieved from login and password.
[2025-04-04T15:19:48.021+0000] {base.py:73} INFO - Using connection ID 'minio_s3' for task execution.
[2025-04-04T15:19:48.057+0000] {connection_wrapper.py:334} INFO - AWS Connection (conn_id='minio_s3', conn_type='aws') credentials retrieved from login and password.
[2025-04-04T15:19:51.148+0000] {base.py:73} INFO - Using connection ID 'minio_s3' for task execution.
[2025-04-04T15:19:51.150+0000] {connection_wrapper.py:334} INFO - AWS Connection (conn_id='minio_s3', conn_type='aws') credentials retrieved from login and password.
[2025-04-04T15:19:54.751+0000] {base.py:73} INFO - Using connection ID 'minio_s3' for task execution.
[2025-04-04T15:19:54.764+0000] {connection_wrapper.py:334} INFO - AWS Connection (conn_id='minio_s3', conn_type='aws') credentials retrieved from login and password.
[2025-04-04T15:20:04.702+0000] {base.py:73} INFO - Using connection ID 'minio_s3' for task execution.
[2025-04-04T15:20:04.717+0000] {connection_wrapper.py:334} INFO - AWS Connection (conn_id='minio_s3', conn_type='aws') credentials retrieved from login and password.
[2025-04-04T15:20:09.352+0000] {base.py:73} INFO - Using connection ID 'minio_s3' for task execution.
[2025-04-04T15:20:09.362+0000] {connection_wrapper.py:334} INFO - AWS Connection (conn_id='minio_s3', conn_type='aws') credentials retrieved from login and password.
[2025-04-04T15:20:15.231+0000] {base.py:73} INFO - Using connection ID 'minio_s3' for task execution.
[2025-04-04T15:20:15.237+0000] {connection_wrapper.py:334} INFO - AWS Connection (conn_id='minio_s3', conn_type='aws') credentials retrieved from login and password.
[2025-04-04T15:20:19.023+0000] {base.py:73} INFO - Using connection ID 'minio_s3' for task execution.
[2025-04-04T15:20:19.036+0000] {connection_wrapper.py:334} INFO - AWS Connection (conn_id='minio_s3', conn_type='aws') credentials retrieved from login and password.
[2025-04-04T15:20:25.205+0000] {base.py:73} INFO - Using connection ID 'minio_s3' for task execution.
[2025-04-04T15:20:25.216+0000] {connection_wrapper.py:334} INFO - AWS Connection (conn_id='minio_s3', conn_type='aws') credentials retrieved from login and password.
[2025-04-04T15:20:33.118+0000] {base.py:73} INFO - Using connection ID 'minio_s3' for task execution.
[2025-04-04T15:20:33.156+0000] {connection_wrapper.py:334} INFO - AWS Connection (conn_id='minio_s3', conn_type='aws') credentials retrieved from login and password.
[2025-04-04T15:20:46.331+0000] {base.py:73} INFO - Using connection ID 'minio_s3' for task execution.
[2025-04-04T15:20:46.355+0000] {connection_wrapper.py:334} INFO - AWS Connection (conn_id='minio_s3', conn_type='aws') credentials retrieved from login and password.
[2025-04-04T15:20:53.334+0000] {base.py:73} INFO - Using connection ID 'minio_s3' for task execution.
[2025-04-04T15:20:53.342+0000] {connection_wrapper.py:334} INFO - AWS Connection (conn_id='minio_s3', conn_type='aws') credentials retrieved from login and password.
[2025-04-04T15:21:01.853+0000] {base.py:73} INFO - Using connection ID 'minio_s3' for task execution.
[2025-04-04T15:21:01.855+0000] {connection_wrapper.py:334} INFO - AWS Connection (conn_id='minio_s3', conn_type='aws') credentials retrieved from login and password.
[2025-04-04T15:21:18.223+0000] {base.py:73} INFO - Using connection ID 'minio_s3' for task execution.
[2025-04-04T15:21:18.292+0000] {connection_wrapper.py:334} INFO - AWS Connection (conn_id='minio_s3', conn_type='aws') credentials retrieved from login and password.
[2025-04-04T15:21:35.486+0000] {base.py:73} INFO - Using connection ID 'minio_s3' for task execution.
[2025-04-04T15:21:35.504+0000] {connection_wrapper.py:334} INFO - AWS Connection (conn_id='minio_s3', conn_type='aws') credentials retrieved from login and password.
[2025-04-04T15:22:37.678+0000] {base.py:73} INFO - Using connection ID 'minio_s3' for task execution.
[2025-04-04T15:22:37.726+0000] {connection_wrapper.py:334} INFO - AWS Connection (conn_id='minio_s3', conn_type='aws') credentials retrieved from login and password.
[2025-04-04T15:23:03.939+0000] {base.py:73} INFO - Using connection ID 'minio_s3' for task execution.
[2025-04-04T15:23:03.942+0000] {connection_wrapper.py:334} INFO - AWS Connection (conn_id='minio_s3', conn_type='aws') credentials retrieved from login and password.
[2025-04-04T15:23:25.717+0000] {base.py:73} INFO - Using connection ID 'minio_s3' for task execution.
[2025-04-04T15:23:25.736+0000] {connection_wrapper.py:334} INFO - AWS Connection (conn_id='minio_s3', conn_type='aws') credentials retrieved from login and password.
[2025-04-04T15:23:49.012+0000] {base.py:73} INFO - Using connection ID 'minio_s3' for task execution.
[2025-04-04T15:23:49.064+0000] {connection_wrapper.py:334} INFO - AWS Connection (conn_id='minio_s3', conn_type='aws') credentials retrieved from login and password.
[2025-04-04T15:24:00.593+0000] {base.py:73} INFO - Using connection ID 'minio_s3' for task execution.
[2025-04-04T15:24:00.614+0000] {connection_wrapper.py:334} INFO - AWS Connection (conn_id='minio_s3', conn_type='aws') credentials retrieved from login and password.
[2025-04-04T15:24:18.856+0000] {base.py:73} INFO - Using connection ID 'minio_s3' for task execution.
[2025-04-04T15:24:18.872+0000] {connection_wrapper.py:334} INFO - AWS Connection (conn_id='minio_s3', conn_type='aws') credentials retrieved from login and password.
[2025-04-04T15:27:07.508+0000] {base.py:73} INFO - Using connection ID 'minio_s3' for task execution.
[2025-04-04T15:27:07.860+0000] {connection_wrapper.py:334} INFO - AWS Connection (conn_id='minio_s3', conn_type='aws') credentials retrieved from login and password.
[2025-04-04T15:28:18.652+0000] {base.py:73} INFO - Using connection ID 'minio_s3' for task execution.
[2025-04-04T15:28:18.718+0000] {connection_wrapper.py:334} INFO - AWS Connection (conn_id='minio_s3', conn_type='aws') credentials retrieved from login and password.
[2025-04-04T15:29:09.455+0000] {base.py:73} INFO - Using connection ID 'minio_s3' for task execution.
[2025-04-04T15:29:09.484+0000] {connection_wrapper.py:334} INFO - AWS Connection (conn_id='minio_s3', conn_type='aws') credentials retrieved from login and password.
[2025-04-04T15:29:26.392+0000] {base.py:73} INFO - Using connection ID 'minio_s3' for task execution.
[2025-04-04T15:29:26.477+0000] {connection_wrapper.py:334} INFO - AWS Connection (conn_id='minio_s3', conn_type='aws') credentials retrieved from login and password.
[2025-04-04T15:29:37.475+0000] {base.py:73} INFO - Using connection ID 'minio_s3' for task execution.
[2025-04-04T15:29:37.482+0000] {connection_wrapper.py:334} INFO - AWS Connection (conn_id='minio_s3', conn_type='aws') credentials retrieved from login and password.
[2025-04-04T15:29:47.132+0000] {base.py:73} INFO - Using connection ID 'minio_s3' for task execution.
[2025-04-04T15:29:47.152+0000] {connection_wrapper.py:334} INFO - AWS Connection (conn_id='minio_s3', conn_type='aws') credentials retrieved from login and password.
[2025-04-04T15:30:20.287+0000] {base.py:73} INFO - Using connection ID 'minio_s3' for task execution.
[2025-04-04T15:30:20.340+0000] {connection_wrapper.py:334} INFO - AWS Connection (conn_id='minio_s3', conn_type='aws') credentials retrieved from login and password.
[2025-04-04T15:33:05.908+0000] {connection.py:432} ERROR - Unable to retrieve connection from secrets backend (MetastoreBackend). Checking subsequent secrets backend.
Traceback (most recent call last):
  File "/home/airflow/.local/lib/python3.7/site-packages/sqlalchemy/engine/base.py", line 3361, in _wrap_pool_connect
    return fn()
  File "/home/airflow/.local/lib/python3.7/site-packages/sqlalchemy/pool/base.py", line 327, in connect
    return _ConnectionFairy._checkout(self)
  File "/home/airflow/.local/lib/python3.7/site-packages/sqlalchemy/pool/base.py", line 894, in _checkout
    fairy = _ConnectionRecord.checkout(pool)
  File "/home/airflow/.local/lib/python3.7/site-packages/sqlalchemy/pool/base.py", line 493, in checkout
    rec = pool._do_get()
  File "/home/airflow/.local/lib/python3.7/site-packages/sqlalchemy/pool/impl.py", line 256, in _do_get
    return self._create_connection()
  File "/home/airflow/.local/lib/python3.7/site-packages/sqlalchemy/pool/base.py", line 273, in _create_connection
    return _ConnectionRecord(self)
  File "/home/airflow/.local/lib/python3.7/site-packages/sqlalchemy/pool/base.py", line 388, in __init__
    self.__connect()
  File "/home/airflow/.local/lib/python3.7/site-packages/sqlalchemy/pool/base.py", line 691, in __connect
    pool.logger.debug("Error on connect(): %s", e)
  File "/home/airflow/.local/lib/python3.7/site-packages/sqlalchemy/util/langhelpers.py", line 72, in __exit__
    with_traceback=exc_tb,
  File "/home/airflow/.local/lib/python3.7/site-packages/sqlalchemy/util/compat.py", line 211, in raise_
    raise exception
  File "/home/airflow/.local/lib/python3.7/site-packages/sqlalchemy/pool/base.py", line 686, in __connect
    self.dbapi_connection = connection = pool._invoke_creator(self)
  File "/home/airflow/.local/lib/python3.7/site-packages/sqlalchemy/engine/create.py", line 578, in connect
    return dialect.connect(*cargs, **cparams)
  File "/home/airflow/.local/lib/python3.7/site-packages/sqlalchemy/engine/default.py", line 598, in connect
    return self.dbapi.connect(*cargs, **cparams)
  File "/home/airflow/.local/lib/python3.7/site-packages/psycopg2/__init__.py", line 122, in connect
    conn = _connect(dsn, connection_factory=connection_factory, **kwasync)
psycopg2.OperationalError: could not translate host name "postgres" to address: Temporary failure in name resolution


The above exception was the direct cause of the following exception:

Traceback (most recent call last):
  File "/home/airflow/.local/lib/python3.7/site-packages/airflow/models/connection.py", line 425, in get_connection_from_secrets
    conn = secrets_backend.get_connection(conn_id=conn_id)
  File "/home/airflow/.local/lib/python3.7/site-packages/airflow/utils/session.py", line 75, in wrapper
    return func(*args, session=session, **kwargs)
  File "/home/airflow/.local/lib/python3.7/site-packages/airflow/secrets/metastore.py", line 39, in get_connection
    conn = session.query(Connection).filter(Connection.conn_id == conn_id).first()
  File "/home/airflow/.local/lib/python3.7/site-packages/sqlalchemy/orm/query.py", line 2824, in first
    return self.limit(1)._iter().first()
  File "/home/airflow/.local/lib/python3.7/site-packages/sqlalchemy/orm/query.py", line 2919, in _iter
    execution_options={"_sa_orm_load_options": self.load_options},
  File "/home/airflow/.local/lib/python3.7/site-packages/sqlalchemy/orm/session.py", line 1713, in execute
    conn = self._connection_for_bind(bind)
  File "/home/airflow/.local/lib/python3.7/site-packages/sqlalchemy/orm/session.py", line 1553, in _connection_for_bind
    engine, execution_options
  File "/home/airflow/.local/lib/python3.7/site-packages/sqlalchemy/orm/session.py", line 747, in _connection_for_bind
    conn = bind.connect()
  File "/home/airflow/.local/lib/python3.7/site-packages/sqlalchemy/engine/base.py", line 3315, in connect
    return self._connection_cls(self, close_with_result=close_with_result)
  File "/home/airflow/.local/lib/python3.7/site-packages/sqlalchemy/engine/base.py", line 96, in __init__
    else engine.raw_connection()
  File "/home/airflow/.local/lib/python3.7/site-packages/sqlalchemy/engine/base.py", line 3394, in raw_connection
    return self._wrap_pool_connect(self.pool.connect, _connection)
  File "/home/airflow/.local/lib/python3.7/site-packages/sqlalchemy/engine/base.py", line 3365, in _wrap_pool_connect
    e, dialect, self
  File "/home/airflow/.local/lib/python3.7/site-packages/sqlalchemy/engine/base.py", line 2199, in _handle_dbapi_exception_noconnection
    sqlalchemy_exception, with_traceback=exc_info[2], from_=e
  File "/home/airflow/.local/lib/python3.7/site-packages/sqlalchemy/util/compat.py", line 211, in raise_
    raise exception
  File "/home/airflow/.local/lib/python3.7/site-packages/sqlalchemy/engine/base.py", line 3361, in _wrap_pool_connect
    return fn()
  File "/home/airflow/.local/lib/python3.7/site-packages/sqlalchemy/pool/base.py", line 327, in connect
    return _ConnectionFairy._checkout(self)
  File "/home/airflow/.local/lib/python3.7/site-packages/sqlalchemy/pool/base.py", line 894, in _checkout
    fairy = _ConnectionRecord.checkout(pool)
  File "/home/airflow/.local/lib/python3.7/site-packages/sqlalchemy/pool/base.py", line 493, in checkout
    rec = pool._do_get()
  File "/home/airflow/.local/lib/python3.7/site-packages/sqlalchemy/pool/impl.py", line 256, in _do_get
    return self._create_connection()
  File "/home/airflow/.local/lib/python3.7/site-packages/sqlalchemy/pool/base.py", line 273, in _create_connection
    return _ConnectionRecord(self)
  File "/home/airflow/.local/lib/python3.7/site-packages/sqlalchemy/pool/base.py", line 388, in __init__
    self.__connect()
  File "/home/airflow/.local/lib/python3.7/site-packages/sqlalchemy/pool/base.py", line 691, in __connect
    pool.logger.debug("Error on connect(): %s", e)
  File "/home/airflow/.local/lib/python3.7/site-packages/sqlalchemy/util/langhelpers.py", line 72, in __exit__
    with_traceback=exc_tb,
  File "/home/airflow/.local/lib/python3.7/site-packages/sqlalchemy/util/compat.py", line 211, in raise_
    raise exception
  File "/home/airflow/.local/lib/python3.7/site-packages/sqlalchemy/pool/base.py", line 686, in __connect
    self.dbapi_connection = connection = pool._invoke_creator(self)
  File "/home/airflow/.local/lib/python3.7/site-packages/sqlalchemy/engine/create.py", line 578, in connect
    return dialect.connect(*cargs, **cparams)
  File "/home/airflow/.local/lib/python3.7/site-packages/sqlalchemy/engine/default.py", line 598, in connect
    return self.dbapi.connect(*cargs, **cparams)
  File "/home/airflow/.local/lib/python3.7/site-packages/psycopg2/__init__.py", line 122, in connect
    conn = _connect(dsn, connection_factory=connection_factory, **kwasync)
sqlalchemy.exc.OperationalError: (psycopg2.OperationalError) could not translate host name "postgres" to address: Temporary failure in name resolution

(Background on this error at: https://sqlalche.me/e/14/e3q8)
[2025-04-04T15:33:08.942+0000] {base_aws.py:133} INFO - No connection ID provided. Fallback on boto3 credential strategy (region_name=None). See: https://boto3.amazonaws.com/v1/documentation/api/latest/guide/configuration.html
[2025-04-04T15:33:06.152+0000] {base_job.py:243} ERROR - LocalTaskJob heartbeat got an exception
Traceback (most recent call last):
  File "/home/airflow/.local/lib/python3.7/site-packages/sqlalchemy/engine/base.py", line 3361, in _wrap_pool_connect
    return fn()
  File "/home/airflow/.local/lib/python3.7/site-packages/sqlalchemy/pool/base.py", line 327, in connect
    return _ConnectionFairy._checkout(self)
  File "/home/airflow/.local/lib/python3.7/site-packages/sqlalchemy/pool/base.py", line 894, in _checkout
    fairy = _ConnectionRecord.checkout(pool)
  File "/home/airflow/.local/lib/python3.7/site-packages/sqlalchemy/pool/base.py", line 493, in checkout
    rec = pool._do_get()
  File "/home/airflow/.local/lib/python3.7/site-packages/sqlalchemy/pool/impl.py", line 256, in _do_get
    return self._create_connection()
  File "/home/airflow/.local/lib/python3.7/site-packages/sqlalchemy/pool/base.py", line 273, in _create_connection
    return _ConnectionRecord(self)
  File "/home/airflow/.local/lib/python3.7/site-packages/sqlalchemy/pool/base.py", line 388, in __init__
    self.__connect()
  File "/home/airflow/.local/lib/python3.7/site-packages/sqlalchemy/pool/base.py", line 691, in __connect
    pool.logger.debug("Error on connect(): %s", e)
  File "/home/airflow/.local/lib/python3.7/site-packages/sqlalchemy/util/langhelpers.py", line 72, in __exit__
    with_traceback=exc_tb,
  File "/home/airflow/.local/lib/python3.7/site-packages/sqlalchemy/util/compat.py", line 211, in raise_
    raise exception
  File "/home/airflow/.local/lib/python3.7/site-packages/sqlalchemy/pool/base.py", line 686, in __connect
    self.dbapi_connection = connection = pool._invoke_creator(self)
  File "/home/airflow/.local/lib/python3.7/site-packages/sqlalchemy/engine/create.py", line 578, in connect
    return dialect.connect(*cargs, **cparams)
  File "/home/airflow/.local/lib/python3.7/site-packages/sqlalchemy/engine/default.py", line 598, in connect
    return self.dbapi.connect(*cargs, **cparams)
  File "/home/airflow/.local/lib/python3.7/site-packages/psycopg2/__init__.py", line 122, in connect
    conn = _connect(dsn, connection_factory=connection_factory, **kwasync)
psycopg2.OperationalError: could not translate host name "postgres" to address: Temporary failure in name resolution


The above exception was the direct cause of the following exception:

Traceback (most recent call last):
  File "/home/airflow/.local/lib/python3.7/site-packages/airflow/jobs/base_job.py", line 233, in heartbeat
    session.merge(self)
  File "/home/airflow/.local/lib/python3.7/site-packages/sqlalchemy/orm/session.py", line 3057, in merge
    _resolve_conflict_map=_resolve_conflict_map,
  File "/home/airflow/.local/lib/python3.7/site-packages/sqlalchemy/orm/session.py", line 3135, in _merge
    options=options,
  File "/home/airflow/.local/lib/python3.7/site-packages/sqlalchemy/orm/session.py", line 2856, in get
    execution_options=execution_options,
  File "/home/airflow/.local/lib/python3.7/site-packages/sqlalchemy/orm/session.py", line 2974, in _get_impl
    load_options=load_options,
  File "/home/airflow/.local/lib/python3.7/site-packages/sqlalchemy/orm/loading.py", line 534, in load_on_pk_identity
    bind_arguments=bind_arguments,
  File "/home/airflow/.local/lib/python3.7/site-packages/sqlalchemy/orm/session.py", line 1713, in execute
    conn = self._connection_for_bind(bind)
  File "/home/airflow/.local/lib/python3.7/site-packages/sqlalchemy/orm/session.py", line 1553, in _connection_for_bind
    engine, execution_options
  File "/home/airflow/.local/lib/python3.7/site-packages/sqlalchemy/orm/session.py", line 747, in _connection_for_bind
    conn = bind.connect()
  File "/home/airflow/.local/lib/python3.7/site-packages/sqlalchemy/engine/base.py", line 3315, in connect
    return self._connection_cls(self, close_with_result=close_with_result)
  File "/home/airflow/.local/lib/python3.7/site-packages/sqlalchemy/engine/base.py", line 96, in __init__
    else engine.raw_connection()
  File "/home/airflow/.local/lib/python3.7/site-packages/sqlalchemy/engine/base.py", line 3394, in raw_connection
    return self._wrap_pool_connect(self.pool.connect, _connection)
  File "/home/airflow/.local/lib/python3.7/site-packages/sqlalchemy/engine/base.py", line 3365, in _wrap_pool_connect
    e, dialect, self
  File "/home/airflow/.local/lib/python3.7/site-packages/sqlalchemy/engine/base.py", line 2199, in _handle_dbapi_exception_noconnection
    sqlalchemy_exception, with_traceback=exc_info[2], from_=e
  File "/home/airflow/.local/lib/python3.7/site-packages/sqlalchemy/util/compat.py", line 211, in raise_
    raise exception
  File "/home/airflow/.local/lib/python3.7/site-packages/sqlalchemy/engine/base.py", line 3361, in _wrap_pool_connect
    return fn()
  File "/home/airflow/.local/lib/python3.7/site-packages/sqlalchemy/pool/base.py", line 327, in connect
    return _ConnectionFairy._checkout(self)
  File "/home/airflow/.local/lib/python3.7/site-packages/sqlalchemy/pool/base.py", line 894, in _checkout
    fairy = _ConnectionRecord.checkout(pool)
  File "/home/airflow/.local/lib/python3.7/site-packages/sqlalchemy/pool/base.py", line 493, in checkout
    rec = pool._do_get()
  File "/home/airflow/.local/lib/python3.7/site-packages/sqlalchemy/pool/impl.py", line 256, in _do_get
    return self._create_connection()
  File "/home/airflow/.local/lib/python3.7/site-packages/sqlalchemy/pool/base.py", line 273, in _create_connection
    return _ConnectionRecord(self)
  File "/home/airflow/.local/lib/python3.7/site-packages/sqlalchemy/pool/base.py", line 388, in __init__
    self.__connect()
  File "/home/airflow/.local/lib/python3.7/site-packages/sqlalchemy/pool/base.py", line 691, in __connect
    pool.logger.debug("Error on connect(): %s", e)
  File "/home/airflow/.local/lib/python3.7/site-packages/sqlalchemy/util/langhelpers.py", line 72, in __exit__
    with_traceback=exc_tb,
  File "/home/airflow/.local/lib/python3.7/site-packages/sqlalchemy/util/compat.py", line 211, in raise_
    raise exception
  File "/home/airflow/.local/lib/python3.7/site-packages/sqlalchemy/pool/base.py", line 686, in __connect
    self.dbapi_connection = connection = pool._invoke_creator(self)
  File "/home/airflow/.local/lib/python3.7/site-packages/sqlalchemy/engine/create.py", line 578, in connect
    return dialect.connect(*cargs, **cparams)
  File "/home/airflow/.local/lib/python3.7/site-packages/sqlalchemy/engine/default.py", line 598, in connect
    return self.dbapi.connect(*cargs, **cparams)
  File "/home/airflow/.local/lib/python3.7/site-packages/psycopg2/__init__.py", line 122, in connect
    conn = _connect(dsn, connection_factory=connection_factory, **kwasync)
sqlalchemy.exc.OperationalError: (psycopg2.OperationalError) could not translate host name "postgres" to address: Temporary failure in name resolution

(Background on this error at: https://sqlalche.me/e/14/e3q8)
[2025-04-04T15:34:34.541+0000] {taskinstance.py:1768} ERROR - Task failed with exception
Traceback (most recent call last):
  File "/home/airflow/.local/lib/python3.7/site-packages/airflow/operators/python.py", line 175, in execute
    return_value = self.execute_callable()
  File "/home/airflow/.local/lib/python3.7/site-packages/airflow/operators/python.py", line 192, in execute_callable
    return self.python_callable(*self.op_args, **self.op_kwargs)
  File "/opt/airflow/dags/dag_data_collect.py", line 87, in download_and_upload_images
    if not check_image_in_s3(new_image_name):
  File "/opt/airflow/dags/dag_data_collect.py", line 57, in check_image_in_s3
    return s3.check_for_key(key, bucket_name)
  File "/home/airflow/.local/lib/python3.7/site-packages/airflow/providers/amazon/aws/hooks/s3.py", line 99, in wrapper
    return func(*bound_args.args, **bound_args.kwargs)
  File "/home/airflow/.local/lib/python3.7/site-packages/airflow/providers/amazon/aws/hooks/s3.py", line 70, in wrapper
    return func(*bound_args.args, **bound_args.kwargs)
  File "/home/airflow/.local/lib/python3.7/site-packages/airflow/providers/amazon/aws/hooks/s3.py", line 481, in check_for_key
    obj = self.head_object(key, bucket_name)
  File "/home/airflow/.local/lib/python3.7/site-packages/airflow/providers/amazon/aws/hooks/s3.py", line 99, in wrapper
    return func(*bound_args.args, **bound_args.kwargs)
  File "/home/airflow/.local/lib/python3.7/site-packages/airflow/providers/amazon/aws/hooks/s3.py", line 70, in wrapper
    return func(*bound_args.args, **bound_args.kwargs)
  File "/home/airflow/.local/lib/python3.7/site-packages/airflow/providers/amazon/aws/hooks/s3.py", line 464, in head_object
    return self.get_conn().head_object(Bucket=bucket_name, Key=key)
  File "/home/airflow/.local/lib/python3.7/site-packages/botocore/client.py", line 530, in _api_call
    return self._make_api_call(operation_name, kwargs)
  File "/home/airflow/.local/lib/python3.7/site-packages/botocore/client.py", line 944, in _make_api_call
    operation_model, request_dict, request_context
  File "/home/airflow/.local/lib/python3.7/site-packages/botocore/client.py", line 966, in _make_request
    return self._endpoint.make_request(operation_model, request_dict)
  File "/home/airflow/.local/lib/python3.7/site-packages/botocore/endpoint.py", line 119, in make_request
    return self._send_request(request_dict, operation_model)
  File "/home/airflow/.local/lib/python3.7/site-packages/botocore/endpoint.py", line 198, in _send_request
    request = self.create_request(request_dict, operation_model)
  File "/home/airflow/.local/lib/python3.7/site-packages/botocore/endpoint.py", line 137, in create_request
    operation_name=operation_model.name,
  File "/home/airflow/.local/lib/python3.7/site-packages/botocore/hooks.py", line 412, in emit
    return self._emitter.emit(aliased_event_name, **kwargs)
  File "/home/airflow/.local/lib/python3.7/site-packages/botocore/hooks.py", line 256, in emit
    return self._emit(event_name, kwargs)
  File "/home/airflow/.local/lib/python3.7/site-packages/botocore/hooks.py", line 239, in _emit
    response = handler(**kwargs)
  File "/home/airflow/.local/lib/python3.7/site-packages/botocore/signers.py", line 105, in handler
    return self.sign(operation_name, request)
  File "/home/airflow/.local/lib/python3.7/site-packages/botocore/signers.py", line 189, in sign
    auth.add_auth(request)
  File "/home/airflow/.local/lib/python3.7/site-packages/botocore/auth.py", line 418, in add_auth
    raise NoCredentialsError()
botocore.exceptions.NoCredentialsError: Unable to locate credentials
[2025-04-04T15:34:36.455+0000] {taskinstance.py:1323} INFO - Marking task as UP_FOR_RETRY. dag_id=download_and_store_images, task_id=download_and_upload_images, execution_date=20250403T151102, start_date=20250404T151215, end_date=20250404T153436
[2025-04-04T15:34:38.500+0000] {standard_task_runner.py:105} ERROR - Failed to execute job 813 for task download_and_upload_images (Unable to locate credentials; 109)
[2025-04-04T15:34:39.692+0000] {local_task_job.py:208} INFO - Task exited with return code 1
[2025-04-04T15:34:41.454+0000] {taskinstance.py:2578} INFO - 0 downstream tasks scheduled from follow-on schedule check
